2020-02-20 10:55:36,343 - rest.api - INFO - Web-service started
2020-02-20 10:55:45,489 - rest.api - ERROR - Exception on /api/departments [GET]
Traceback (most recent call last):
  File "E:\GraduationWork\ENV\lib\site-packages\sqlalchemy\engine\base.py", line 1245, in _execute_context
    self.dialect.do_execute(
  File "E:\GraduationWork\ENV\lib\site-packages\sqlalchemy\engine\default.py", line 581, in do_execute
    cursor.execute(statement, parameters)
sqlite3.OperationalError: no such table: department

The above exception was the direct cause of the following exception:

Traceback (most recent call last):
  File "E:\GraduationWork\ENV\lib\site-packages\flask\app.py", line 1949, in full_dispatch_request
    rv = self.dispatch_request()
  File "E:\GraduationWork\ENV\lib\site-packages\flask\app.py", line 1935, in dispatch_request
    return self.view_functions[rule.endpoint](**req.view_args)
  File "E:\GraduationWork\ENV\lib\site-packages\flask_restful\__init__.py", line 458, in wrapper
    resp = resource(*args, **kwargs)
  File "E:\GraduationWork\ENV\lib\site-packages\flask\views.py", line 89, in view
    return self.dispatch_request(*args, **kwargs)
  File "E:\GraduationWork\ENV\lib\site-packages\flask_restful\__init__.py", line 573, in dispatch_request
    resp = meth(*args, **kwargs)
  File "E:\GraduationWork\DepartmentHandler\department-app\rest\api.py", line 49, in get
    data = crud.Departments.get_all()
  File "E:\GraduationWork\DepartmentHandler\department-app\service\crud.py", line 32, in get_all
    departments = Department.query.all()
  File "E:\GraduationWork\ENV\lib\site-packages\sqlalchemy\orm\query.py", line 3211, in all
    return list(self)
  File "E:\GraduationWork\ENV\lib\site-packages\sqlalchemy\orm\query.py", line 3367, in __iter__
    return self._execute_and_instances(context)
  File "E:\GraduationWork\ENV\lib\site-packages\sqlalchemy\orm\query.py", line 3392, in _execute_and_instances
    result = conn.execute(querycontext.statement, self._params)
  File "E:\GraduationWork\ENV\lib\site-packages\sqlalchemy\engine\base.py", line 982, in execute
    return meth(self, multiparams, params)
  File "E:\GraduationWork\ENV\lib\site-packages\sqlalchemy\sql\elements.py", line 287, in _execute_on_connection
    return connection._execute_clauseelement(self, multiparams, params)
  File "E:\GraduationWork\ENV\lib\site-packages\sqlalchemy\engine\base.py", line 1095, in _execute_clauseelement
    ret = self._execute_context(
  File "E:\GraduationWork\ENV\lib\site-packages\sqlalchemy\engine\base.py", line 1249, in _execute_context
    self._handle_dbapi_exception(
  File "E:\GraduationWork\ENV\lib\site-packages\sqlalchemy\engine\base.py", line 1476, in _handle_dbapi_exception
    util.raise_from_cause(sqlalchemy_exception, exc_info)
  File "E:\GraduationWork\ENV\lib\site-packages\sqlalchemy\util\compat.py", line 398, in raise_from_cause
    reraise(type(exception), exception, tb=exc_tb, cause=cause)
  File "E:\GraduationWork\ENV\lib\site-packages\sqlalchemy\util\compat.py", line 152, in reraise
    raise value.with_traceback(tb)
  File "E:\GraduationWork\ENV\lib\site-packages\sqlalchemy\engine\base.py", line 1245, in _execute_context
    self.dialect.do_execute(
  File "E:\GraduationWork\ENV\lib\site-packages\sqlalchemy\engine\default.py", line 581, in do_execute
    cursor.execute(statement, parameters)
sqlalchemy.exc.OperationalError: (sqlite3.OperationalError) no such table: department
[SQL: SELECT department.id AS department_id, department.name AS department_name 
FROM department]
(Background on this error at: http://sqlalche.me/e/e3q8)
2020-02-20 10:55:47,307 - service.crud - DEBUG - List of employees was returned
2020-02-20 10:55:47,312 - rest.api - ERROR - Exception on /api/employees [GET]
Traceback (most recent call last):
  File "E:\GraduationWork\ENV\lib\site-packages\sqlalchemy\engine\base.py", line 1245, in _execute_context
    self.dialect.do_execute(
  File "E:\GraduationWork\ENV\lib\site-packages\sqlalchemy\engine\default.py", line 581, in do_execute
    cursor.execute(statement, parameters)
sqlite3.OperationalError: no such table: employee

The above exception was the direct cause of the following exception:

Traceback (most recent call last):
  File "E:\GraduationWork\ENV\lib\site-packages\flask\app.py", line 1949, in full_dispatch_request
    rv = self.dispatch_request()
  File "E:\GraduationWork\ENV\lib\site-packages\flask\app.py", line 1935, in dispatch_request
    return self.view_functions[rule.endpoint](**req.view_args)
  File "E:\GraduationWork\ENV\lib\site-packages\flask_restful\__init__.py", line 458, in wrapper
    resp = resource(*args, **kwargs)
  File "E:\GraduationWork\ENV\lib\site-packages\flask\views.py", line 89, in view
    return self.dispatch_request(*args, **kwargs)
  File "E:\GraduationWork\ENV\lib\site-packages\flask_restful\__init__.py", line 573, in dispatch_request
    resp = meth(*args, **kwargs)
  File "E:\GraduationWork\DepartmentHandler\department-app\rest\api.py", line 179, in get
    employees = crud.Employees.get_all()
  File "E:\GraduationWork\DepartmentHandler\department-app\service\crud.py", line 125, in get_all
    return Employee.query.all()
  File "E:\GraduationWork\ENV\lib\site-packages\sqlalchemy\orm\query.py", line 3211, in all
    return list(self)
  File "E:\GraduationWork\ENV\lib\site-packages\sqlalchemy\orm\query.py", line 3367, in __iter__
    return self._execute_and_instances(context)
  File "E:\GraduationWork\ENV\lib\site-packages\sqlalchemy\orm\query.py", line 3392, in _execute_and_instances
    result = conn.execute(querycontext.statement, self._params)
  File "E:\GraduationWork\ENV\lib\site-packages\sqlalchemy\engine\base.py", line 982, in execute
    return meth(self, multiparams, params)
  File "E:\GraduationWork\ENV\lib\site-packages\sqlalchemy\sql\elements.py", line 287, in _execute_on_connection
    return connection._execute_clauseelement(self, multiparams, params)
  File "E:\GraduationWork\ENV\lib\site-packages\sqlalchemy\engine\base.py", line 1095, in _execute_clauseelement
    ret = self._execute_context(
  File "E:\GraduationWork\ENV\lib\site-packages\sqlalchemy\engine\base.py", line 1249, in _execute_context
    self._handle_dbapi_exception(
  File "E:\GraduationWork\ENV\lib\site-packages\sqlalchemy\engine\base.py", line 1476, in _handle_dbapi_exception
    util.raise_from_cause(sqlalchemy_exception, exc_info)
  File "E:\GraduationWork\ENV\lib\site-packages\sqlalchemy\util\compat.py", line 398, in raise_from_cause
    reraise(type(exception), exception, tb=exc_tb, cause=cause)
  File "E:\GraduationWork\ENV\lib\site-packages\sqlalchemy\util\compat.py", line 152, in reraise
    raise value.with_traceback(tb)
  File "E:\GraduationWork\ENV\lib\site-packages\sqlalchemy\engine\base.py", line 1245, in _execute_context
    self.dialect.do_execute(
  File "E:\GraduationWork\ENV\lib\site-packages\sqlalchemy\engine\default.py", line 581, in do_execute
    cursor.execute(statement, parameters)
sqlalchemy.exc.OperationalError: (sqlite3.OperationalError) no such table: employee
[SQL: SELECT employee.id AS employee_id, employee.name AS employee_name, employee.department_id AS employee_department_id, employee.date_of_birthday AS employee_date_of_birthday, employee.salary AS employee_salary 
FROM employee]
(Background on this error at: http://sqlalche.me/e/e3q8)
2020-02-20 10:55:48,580 - rest.api - ERROR - Exception on /api/departments [GET]
Traceback (most recent call last):
  File "E:\GraduationWork\ENV\lib\site-packages\sqlalchemy\engine\base.py", line 1245, in _execute_context
    self.dialect.do_execute(
  File "E:\GraduationWork\ENV\lib\site-packages\sqlalchemy\engine\default.py", line 581, in do_execute
    cursor.execute(statement, parameters)
sqlite3.OperationalError: no such table: department

The above exception was the direct cause of the following exception:

Traceback (most recent call last):
  File "E:\GraduationWork\ENV\lib\site-packages\flask\app.py", line 1949, in full_dispatch_request
    rv = self.dispatch_request()
  File "E:\GraduationWork\ENV\lib\site-packages\flask\app.py", line 1935, in dispatch_request
    return self.view_functions[rule.endpoint](**req.view_args)
  File "E:\GraduationWork\ENV\lib\site-packages\flask_restful\__init__.py", line 458, in wrapper
    resp = resource(*args, **kwargs)
  File "E:\GraduationWork\ENV\lib\site-packages\flask\views.py", line 89, in view
    return self.dispatch_request(*args, **kwargs)
  File "E:\GraduationWork\ENV\lib\site-packages\flask_restful\__init__.py", line 573, in dispatch_request
    resp = meth(*args, **kwargs)
  File "E:\GraduationWork\DepartmentHandler\department-app\rest\api.py", line 49, in get
    data = crud.Departments.get_all()
  File "E:\GraduationWork\DepartmentHandler\department-app\service\crud.py", line 32, in get_all
    departments = Department.query.all()
  File "E:\GraduationWork\ENV\lib\site-packages\sqlalchemy\orm\query.py", line 3211, in all
    return list(self)
  File "E:\GraduationWork\ENV\lib\site-packages\sqlalchemy\orm\query.py", line 3367, in __iter__
    return self._execute_and_instances(context)
  File "E:\GraduationWork\ENV\lib\site-packages\sqlalchemy\orm\query.py", line 3392, in _execute_and_instances
    result = conn.execute(querycontext.statement, self._params)
  File "E:\GraduationWork\ENV\lib\site-packages\sqlalchemy\engine\base.py", line 982, in execute
    return meth(self, multiparams, params)
  File "E:\GraduationWork\ENV\lib\site-packages\sqlalchemy\sql\elements.py", line 287, in _execute_on_connection
    return connection._execute_clauseelement(self, multiparams, params)
  File "E:\GraduationWork\ENV\lib\site-packages\sqlalchemy\engine\base.py", line 1095, in _execute_clauseelement
    ret = self._execute_context(
  File "E:\GraduationWork\ENV\lib\site-packages\sqlalchemy\engine\base.py", line 1249, in _execute_context
    self._handle_dbapi_exception(
  File "E:\GraduationWork\ENV\lib\site-packages\sqlalchemy\engine\base.py", line 1476, in _handle_dbapi_exception
    util.raise_from_cause(sqlalchemy_exception, exc_info)
  File "E:\GraduationWork\ENV\lib\site-packages\sqlalchemy\util\compat.py", line 398, in raise_from_cause
    reraise(type(exception), exception, tb=exc_tb, cause=cause)
  File "E:\GraduationWork\ENV\lib\site-packages\sqlalchemy\util\compat.py", line 152, in reraise
    raise value.with_traceback(tb)
  File "E:\GraduationWork\ENV\lib\site-packages\sqlalchemy\engine\base.py", line 1245, in _execute_context
    self.dialect.do_execute(
  File "E:\GraduationWork\ENV\lib\site-packages\sqlalchemy\engine\default.py", line 581, in do_execute
    cursor.execute(statement, parameters)
sqlalchemy.exc.OperationalError: (sqlite3.OperationalError) no such table: department
[SQL: SELECT department.id AS department_id, department.name AS department_name 
FROM department]
(Background on this error at: http://sqlalche.me/e/e3q8)
2020-02-20 11:10:36,062 - rest.api - ERROR - Exception on /api/departments [GET]
Traceback (most recent call last):
  File "E:\GraduationWork\ENV\lib\site-packages\sqlalchemy\engine\base.py", line 1245, in _execute_context
    self.dialect.do_execute(
  File "E:\GraduationWork\ENV\lib\site-packages\sqlalchemy\engine\default.py", line 581, in do_execute
    cursor.execute(statement, parameters)
sqlite3.OperationalError: no such table: department

The above exception was the direct cause of the following exception:

Traceback (most recent call last):
  File "E:\GraduationWork\ENV\lib\site-packages\flask\app.py", line 1949, in full_dispatch_request
    rv = self.dispatch_request()
  File "E:\GraduationWork\ENV\lib\site-packages\flask\app.py", line 1935, in dispatch_request
    return self.view_functions[rule.endpoint](**req.view_args)
  File "E:\GraduationWork\ENV\lib\site-packages\flask_restful\__init__.py", line 458, in wrapper
    resp = resource(*args, **kwargs)
  File "E:\GraduationWork\ENV\lib\site-packages\flask\views.py", line 89, in view
    return self.dispatch_request(*args, **kwargs)
  File "E:\GraduationWork\ENV\lib\site-packages\flask_restful\__init__.py", line 573, in dispatch_request
    resp = meth(*args, **kwargs)
  File "E:\GraduationWork\DepartmentHandler\department-app\rest\api.py", line 49, in get
    data = crud.Departments.get_all()
  File "E:\GraduationWork\DepartmentHandler\department-app\service\crud.py", line 32, in get_all
    departments = Department.query.all()
  File "E:\GraduationWork\ENV\lib\site-packages\sqlalchemy\orm\query.py", line 3211, in all
    return list(self)
  File "E:\GraduationWork\ENV\lib\site-packages\sqlalchemy\orm\query.py", line 3367, in __iter__
    return self._execute_and_instances(context)
  File "E:\GraduationWork\ENV\lib\site-packages\sqlalchemy\orm\query.py", line 3392, in _execute_and_instances
    result = conn.execute(querycontext.statement, self._params)
  File "E:\GraduationWork\ENV\lib\site-packages\sqlalchemy\engine\base.py", line 982, in execute
    return meth(self, multiparams, params)
  File "E:\GraduationWork\ENV\lib\site-packages\sqlalchemy\sql\elements.py", line 287, in _execute_on_connection
    return connection._execute_clauseelement(self, multiparams, params)
  File "E:\GraduationWork\ENV\lib\site-packages\sqlalchemy\engine\base.py", line 1095, in _execute_clauseelement
    ret = self._execute_context(
  File "E:\GraduationWork\ENV\lib\site-packages\sqlalchemy\engine\base.py", line 1249, in _execute_context
    self._handle_dbapi_exception(
  File "E:\GraduationWork\ENV\lib\site-packages\sqlalchemy\engine\base.py", line 1476, in _handle_dbapi_exception
    util.raise_from_cause(sqlalchemy_exception, exc_info)
  File "E:\GraduationWork\ENV\lib\site-packages\sqlalchemy\util\compat.py", line 398, in raise_from_cause
    reraise(type(exception), exception, tb=exc_tb, cause=cause)
  File "E:\GraduationWork\ENV\lib\site-packages\sqlalchemy\util\compat.py", line 152, in reraise
    raise value.with_traceback(tb)
  File "E:\GraduationWork\ENV\lib\site-packages\sqlalchemy\engine\base.py", line 1245, in _execute_context
    self.dialect.do_execute(
  File "E:\GraduationWork\ENV\lib\site-packages\sqlalchemy\engine\default.py", line 581, in do_execute
    cursor.execute(statement, parameters)
sqlalchemy.exc.OperationalError: (sqlite3.OperationalError) no such table: department
[SQL: SELECT department.id AS department_id, department.name AS department_name 
FROM department]
(Background on this error at: http://sqlalche.me/e/e3q8)
2020-02-20 12:32:06,248 - rest.api - INFO - Web-service started
2020-02-20 12:33:37,243 - rest.api - INFO - Web-service started
2020-02-20 12:33:42,828 - service.crud - DEBUG - Department 10001 was returned
2020-02-20 12:37:05,388 - rest.api - INFO - Web-service started
2020-02-20 12:37:12,988 - service.crud - DEBUG - Department 10001 was returned
2020-02-20 12:41:59,709 - rest.api - INFO - Web-service started
2020-02-20 12:42:12,699 - service.crud - DEBUG - Department 10001 was deleted
2020-02-20 12:42:12,879 - service.crud - DEBUG - Department 10001 is not exist
2020-02-20 12:42:16,494 - service.crud - DEBUG - Department 10001 was returned
2020-02-20 12:42:20,928 - service.crud - DEBUG - List of department was returned
2020-02-20 12:43:23,829 - rest.api - INFO - Web-service started
2020-02-20 12:43:28,969 - service.crud - DEBUG - Department 10002 was added
2020-02-20 12:44:18,579 - rest.api - INFO - Web-service started
2020-02-20 12:44:18,638 - service.crud - DEBUG - Department 10002 was added
2020-02-20 12:52:25,009 - rest.api - INFO - Web-service started
2020-02-20 12:52:25,069 - service.crud - DEBUG - Department 10002 was added
2020-02-20 12:52:25,084 - service.crud - DEBUG - Department 10001 was deleted
2020-02-20 12:52:25,084 - service.crud - DEBUG - Department 10001 is not exist
2020-02-20 12:52:25,089 - service.crud - DEBUG - Department 10001 was returned
2020-02-20 12:52:25,104 - service.crud - DEBUG - List of department was returned
2020-02-20 12:52:25,222 - service.crud - DEBUG - Department 10001 was updated
2020-02-20 12:54:00,569 - rest.api - INFO - Web-service started
2020-02-20 12:54:00,627 - service.crud - DEBUG - Department 10001 was updated
2020-02-20 12:56:23,715 - rest.api - INFO - Web-service started
2020-02-20 12:56:23,769 - service.crud - DEBUG - Department 10001 was updated
2020-02-20 12:56:39,616 - rest.api - INFO - Web-service started
2020-02-20 12:56:39,669 - service.crud - DEBUG - Department 10001 was updated
2020-02-20 12:57:28,029 - rest.api - INFO - Web-service started
2020-02-20 12:57:28,089 - service.crud - DEBUG - Department 10001 was updated
2020-02-20 12:58:11,039 - rest.api - INFO - Web-service started
2020-02-20 12:58:11,089 - service.crud - DEBUG - Department 10001 was returned
2020-02-20 12:58:24,059 - rest.api - INFO - Web-service started
2020-02-20 12:58:24,109 - service.crud - DEBUG - Department 10001 was updated
2020-02-20 12:58:37,199 - rest.api - INFO - Web-service started
2020-02-20 12:58:37,259 - service.crud - DEBUG - Department 10001 was updated
2020-02-20 12:59:41,519 - rest.api - INFO - Web-service started
2020-02-20 12:59:41,589 - service.crud - DEBUG - Department 10001 was updated
2020-02-20 13:01:45,529 - rest.api - INFO - Web-service started
2020-02-20 13:01:45,589 - service.crud - DEBUG - Department 10001 was updated
2020-02-20 13:01:45,589 - service.crud - DEBUG - []
2020-02-20 13:02:52,879 - rest.api - INFO - Web-service started
2020-02-20 13:02:52,929 - service.crud - DEBUG - <Department id=10001 + Test Department + [<Employee> name = Steven Gray, <Employee> name = John Spins]>
2020-02-20 13:02:52,929 - service.crud - DEBUG - Department 10001 was updated
2020-02-20 13:02:52,929 - service.crud - DEBUG - <Department id=10002 + UpdatedDepartment + [<Employee> name = Steven Gray, <Employee> name = John Spins]>
2020-02-20 13:04:11,639 - rest.api - INFO - Web-service started
2020-02-20 13:04:11,710 - service.crud - DEBUG - [<Employee> name = Steven Gray, <Employee> name = John Spins]
2020-02-20 13:04:11,710 - service.crud - DEBUG - Department 10001 was updated
2020-02-20 13:04:11,710 - service.crud - DEBUG - [<Employee> name = Steven Gray, <Employee> name = John Spins]
2020-02-20 13:04:42,630 - rest.api - INFO - Web-service started
2020-02-20 13:04:42,680 - service.crud - DEBUG - Department 10001 was updated
2020-02-20 13:04:42,689 - service.crud - DEBUG - []
2020-02-20 14:13:41,793 - rest.api - ERROR - Exception on /api/departments [GET]
Traceback (most recent call last):
  File "E:\GraduationWork\ENV\lib\site-packages\sqlalchemy\engine\base.py", line 1245, in _execute_context
    self.dialect.do_execute(
  File "E:\GraduationWork\ENV\lib\site-packages\sqlalchemy\engine\default.py", line 581, in do_execute
    cursor.execute(statement, parameters)
sqlite3.OperationalError: no such table: department

The above exception was the direct cause of the following exception:

Traceback (most recent call last):
  File "E:\GraduationWork\ENV\lib\site-packages\flask\app.py", line 1949, in full_dispatch_request
    rv = self.dispatch_request()
  File "E:\GraduationWork\ENV\lib\site-packages\flask\app.py", line 1935, in dispatch_request
    return self.view_functions[rule.endpoint](**req.view_args)
  File "E:\GraduationWork\ENV\lib\site-packages\flask_restful\__init__.py", line 458, in wrapper
    resp = resource(*args, **kwargs)
  File "E:\GraduationWork\ENV\lib\site-packages\flask\views.py", line 89, in view
    return self.dispatch_request(*args, **kwargs)
  File "E:\GraduationWork\ENV\lib\site-packages\flask_restful\__init__.py", line 573, in dispatch_request
    resp = meth(*args, **kwargs)
  File "E:\GraduationWork\DepartmentHandler\department-app\rest\api.py", line 49, in get
    data = crud.Departments.get_all()
  File "E:\GraduationWork\DepartmentHandler\department-app\service\crud.py", line 32, in get_all
    departments = Department.query.all()
  File "E:\GraduationWork\ENV\lib\site-packages\sqlalchemy\orm\query.py", line 3211, in all
    return list(self)
  File "E:\GraduationWork\ENV\lib\site-packages\sqlalchemy\orm\query.py", line 3367, in __iter__
    return self._execute_and_instances(context)
  File "E:\GraduationWork\ENV\lib\site-packages\sqlalchemy\orm\query.py", line 3392, in _execute_and_instances
    result = conn.execute(querycontext.statement, self._params)
  File "E:\GraduationWork\ENV\lib\site-packages\sqlalchemy\engine\base.py", line 982, in execute
    return meth(self, multiparams, params)
  File "E:\GraduationWork\ENV\lib\site-packages\sqlalchemy\sql\elements.py", line 287, in _execute_on_connection
    return connection._execute_clauseelement(self, multiparams, params)
  File "E:\GraduationWork\ENV\lib\site-packages\sqlalchemy\engine\base.py", line 1095, in _execute_clauseelement
    ret = self._execute_context(
  File "E:\GraduationWork\ENV\lib\site-packages\sqlalchemy\engine\base.py", line 1249, in _execute_context
    self._handle_dbapi_exception(
  File "E:\GraduationWork\ENV\lib\site-packages\sqlalchemy\engine\base.py", line 1476, in _handle_dbapi_exception
    util.raise_from_cause(sqlalchemy_exception, exc_info)
  File "E:\GraduationWork\ENV\lib\site-packages\sqlalchemy\util\compat.py", line 398, in raise_from_cause
    reraise(type(exception), exception, tb=exc_tb, cause=cause)
  File "E:\GraduationWork\ENV\lib\site-packages\sqlalchemy\util\compat.py", line 152, in reraise
    raise value.with_traceback(tb)
  File "E:\GraduationWork\ENV\lib\site-packages\sqlalchemy\engine\base.py", line 1245, in _execute_context
    self.dialect.do_execute(
  File "E:\GraduationWork\ENV\lib\site-packages\sqlalchemy\engine\default.py", line 581, in do_execute
    cursor.execute(statement, parameters)
sqlalchemy.exc.OperationalError: (sqlite3.OperationalError) no such table: department
[SQL: SELECT department.id AS department_id, department.name AS department_name 
FROM department]
(Background on this error at: http://sqlalche.me/e/e3q8)
2020-02-20 14:13:48,929 - rest.api - ERROR - Exception on /api/departments [GET]
Traceback (most recent call last):
  File "E:\GraduationWork\ENV\lib\site-packages\sqlalchemy\engine\base.py", line 1245, in _execute_context
    self.dialect.do_execute(
  File "E:\GraduationWork\ENV\lib\site-packages\sqlalchemy\engine\default.py", line 581, in do_execute
    cursor.execute(statement, parameters)
sqlite3.OperationalError: no such table: department

The above exception was the direct cause of the following exception:

Traceback (most recent call last):
  File "E:\GraduationWork\ENV\lib\site-packages\flask\app.py", line 1949, in full_dispatch_request
    rv = self.dispatch_request()
  File "E:\GraduationWork\ENV\lib\site-packages\flask\app.py", line 1935, in dispatch_request
    return self.view_functions[rule.endpoint](**req.view_args)
  File "E:\GraduationWork\ENV\lib\site-packages\flask_restful\__init__.py", line 458, in wrapper
    resp = resource(*args, **kwargs)
  File "E:\GraduationWork\ENV\lib\site-packages\flask\views.py", line 89, in view
    return self.dispatch_request(*args, **kwargs)
  File "E:\GraduationWork\ENV\lib\site-packages\flask_restful\__init__.py", line 573, in dispatch_request
    resp = meth(*args, **kwargs)
  File "E:\GraduationWork\DepartmentHandler\department-app\rest\api.py", line 49, in get
    data = crud.Departments.get_all()
  File "E:\GraduationWork\DepartmentHandler\department-app\service\crud.py", line 32, in get_all
    departments = Department.query.all()
  File "E:\GraduationWork\ENV\lib\site-packages\sqlalchemy\orm\query.py", line 3211, in all
    return list(self)
  File "E:\GraduationWork\ENV\lib\site-packages\sqlalchemy\orm\query.py", line 3367, in __iter__
    return self._execute_and_instances(context)
  File "E:\GraduationWork\ENV\lib\site-packages\sqlalchemy\orm\query.py", line 3392, in _execute_and_instances
    result = conn.execute(querycontext.statement, self._params)
  File "E:\GraduationWork\ENV\lib\site-packages\sqlalchemy\engine\base.py", line 982, in execute
    return meth(self, multiparams, params)
  File "E:\GraduationWork\ENV\lib\site-packages\sqlalchemy\sql\elements.py", line 287, in _execute_on_connection
    return connection._execute_clauseelement(self, multiparams, params)
  File "E:\GraduationWork\ENV\lib\site-packages\sqlalchemy\engine\base.py", line 1095, in _execute_clauseelement
    ret = self._execute_context(
  File "E:\GraduationWork\ENV\lib\site-packages\sqlalchemy\engine\base.py", line 1249, in _execute_context
    self._handle_dbapi_exception(
  File "E:\GraduationWork\ENV\lib\site-packages\sqlalchemy\engine\base.py", line 1476, in _handle_dbapi_exception
    util.raise_from_cause(sqlalchemy_exception, exc_info)
  File "E:\GraduationWork\ENV\lib\site-packages\sqlalchemy\util\compat.py", line 398, in raise_from_cause
    reraise(type(exception), exception, tb=exc_tb, cause=cause)
  File "E:\GraduationWork\ENV\lib\site-packages\sqlalchemy\util\compat.py", line 152, in reraise
    raise value.with_traceback(tb)
  File "E:\GraduationWork\ENV\lib\site-packages\sqlalchemy\engine\base.py", line 1245, in _execute_context
    self.dialect.do_execute(
  File "E:\GraduationWork\ENV\lib\site-packages\sqlalchemy\engine\default.py", line 581, in do_execute
    cursor.execute(statement, parameters)
sqlalchemy.exc.OperationalError: (sqlite3.OperationalError) no such table: department
[SQL: SELECT department.id AS department_id, department.name AS department_name 
FROM department]
(Background on this error at: http://sqlalche.me/e/e3q8)
2020-02-20 14:13:49,956 - service.crud - DEBUG - List of employees was returned
2020-02-20 14:13:49,956 - rest.api - ERROR - Exception on /api/employees [GET]
Traceback (most recent call last):
  File "E:\GraduationWork\ENV\lib\site-packages\sqlalchemy\engine\base.py", line 1245, in _execute_context
    self.dialect.do_execute(
  File "E:\GraduationWork\ENV\lib\site-packages\sqlalchemy\engine\default.py", line 581, in do_execute
    cursor.execute(statement, parameters)
sqlite3.OperationalError: no such table: employee

The above exception was the direct cause of the following exception:

Traceback (most recent call last):
  File "E:\GraduationWork\ENV\lib\site-packages\flask\app.py", line 1949, in full_dispatch_request
    rv = self.dispatch_request()
  File "E:\GraduationWork\ENV\lib\site-packages\flask\app.py", line 1935, in dispatch_request
    return self.view_functions[rule.endpoint](**req.view_args)
  File "E:\GraduationWork\ENV\lib\site-packages\flask_restful\__init__.py", line 458, in wrapper
    resp = resource(*args, **kwargs)
  File "E:\GraduationWork\ENV\lib\site-packages\flask\views.py", line 89, in view
    return self.dispatch_request(*args, **kwargs)
  File "E:\GraduationWork\ENV\lib\site-packages\flask_restful\__init__.py", line 573, in dispatch_request
    resp = meth(*args, **kwargs)
  File "E:\GraduationWork\DepartmentHandler\department-app\rest\api.py", line 179, in get
    employees = crud.Employees.get_all()
  File "E:\GraduationWork\DepartmentHandler\department-app\service\crud.py", line 125, in get_all
    :rtype: list
  File "E:\GraduationWork\ENV\lib\site-packages\sqlalchemy\orm\query.py", line 3211, in all
    return list(self)
  File "E:\GraduationWork\ENV\lib\site-packages\sqlalchemy\orm\query.py", line 3367, in __iter__
    return self._execute_and_instances(context)
  File "E:\GraduationWork\ENV\lib\site-packages\sqlalchemy\orm\query.py", line 3392, in _execute_and_instances
    result = conn.execute(querycontext.statement, self._params)
  File "E:\GraduationWork\ENV\lib\site-packages\sqlalchemy\engine\base.py", line 982, in execute
    return meth(self, multiparams, params)
  File "E:\GraduationWork\ENV\lib\site-packages\sqlalchemy\sql\elements.py", line 287, in _execute_on_connection
    return connection._execute_clauseelement(self, multiparams, params)
  File "E:\GraduationWork\ENV\lib\site-packages\sqlalchemy\engine\base.py", line 1095, in _execute_clauseelement
    ret = self._execute_context(
  File "E:\GraduationWork\ENV\lib\site-packages\sqlalchemy\engine\base.py", line 1249, in _execute_context
    self._handle_dbapi_exception(
  File "E:\GraduationWork\ENV\lib\site-packages\sqlalchemy\engine\base.py", line 1476, in _handle_dbapi_exception
    util.raise_from_cause(sqlalchemy_exception, exc_info)
  File "E:\GraduationWork\ENV\lib\site-packages\sqlalchemy\util\compat.py", line 398, in raise_from_cause
    reraise(type(exception), exception, tb=exc_tb, cause=cause)
  File "E:\GraduationWork\ENV\lib\site-packages\sqlalchemy\util\compat.py", line 152, in reraise
    raise value.with_traceback(tb)
  File "E:\GraduationWork\ENV\lib\site-packages\sqlalchemy\engine\base.py", line 1245, in _execute_context
    self.dialect.do_execute(
  File "E:\GraduationWork\ENV\lib\site-packages\sqlalchemy\engine\default.py", line 581, in do_execute
    cursor.execute(statement, parameters)
sqlalchemy.exc.OperationalError: (sqlite3.OperationalError) no such table: employee
[SQL: SELECT employee.id AS employee_id, employee.name AS employee_name, employee.department_id AS employee_department_id, employee.date_of_birthday AS employee_date_of_birthday, employee.salary AS employee_salary 
FROM employee]
(Background on this error at: http://sqlalche.me/e/e3q8)
2020-02-20 14:13:58,954 - rest.api - ERROR - Exception on /api/departments [GET]
Traceback (most recent call last):
  File "E:\GraduationWork\ENV\lib\site-packages\sqlalchemy\engine\base.py", line 1245, in _execute_context
    self.dialect.do_execute(
  File "E:\GraduationWork\ENV\lib\site-packages\sqlalchemy\engine\default.py", line 581, in do_execute
    cursor.execute(statement, parameters)
sqlite3.OperationalError: no such table: department

The above exception was the direct cause of the following exception:

Traceback (most recent call last):
  File "E:\GraduationWork\ENV\lib\site-packages\flask\app.py", line 1949, in full_dispatch_request
    rv = self.dispatch_request()
  File "E:\GraduationWork\ENV\lib\site-packages\flask\app.py", line 1935, in dispatch_request
    return self.view_functions[rule.endpoint](**req.view_args)
  File "E:\GraduationWork\ENV\lib\site-packages\flask_restful\__init__.py", line 458, in wrapper
    resp = resource(*args, **kwargs)
  File "E:\GraduationWork\ENV\lib\site-packages\flask\views.py", line 89, in view
    return self.dispatch_request(*args, **kwargs)
  File "E:\GraduationWork\ENV\lib\site-packages\flask_restful\__init__.py", line 573, in dispatch_request
    resp = meth(*args, **kwargs)
  File "E:\GraduationWork\DepartmentHandler\department-app\rest\api.py", line 49, in get
    data = crud.Departments.get_all()
  File "E:\GraduationWork\DepartmentHandler\department-app\service\crud.py", line 32, in get_all
    departments = Department.query.all()
  File "E:\GraduationWork\ENV\lib\site-packages\sqlalchemy\orm\query.py", line 3211, in all
    return list(self)
  File "E:\GraduationWork\ENV\lib\site-packages\sqlalchemy\orm\query.py", line 3367, in __iter__
    return self._execute_and_instances(context)
  File "E:\GraduationWork\ENV\lib\site-packages\sqlalchemy\orm\query.py", line 3392, in _execute_and_instances
    result = conn.execute(querycontext.statement, self._params)
  File "E:\GraduationWork\ENV\lib\site-packages\sqlalchemy\engine\base.py", line 982, in execute
    return meth(self, multiparams, params)
  File "E:\GraduationWork\ENV\lib\site-packages\sqlalchemy\sql\elements.py", line 287, in _execute_on_connection
    return connection._execute_clauseelement(self, multiparams, params)
  File "E:\GraduationWork\ENV\lib\site-packages\sqlalchemy\engine\base.py", line 1095, in _execute_clauseelement
    ret = self._execute_context(
  File "E:\GraduationWork\ENV\lib\site-packages\sqlalchemy\engine\base.py", line 1249, in _execute_context
    self._handle_dbapi_exception(
  File "E:\GraduationWork\ENV\lib\site-packages\sqlalchemy\engine\base.py", line 1476, in _handle_dbapi_exception
    util.raise_from_cause(sqlalchemy_exception, exc_info)
  File "E:\GraduationWork\ENV\lib\site-packages\sqlalchemy\util\compat.py", line 398, in raise_from_cause
    reraise(type(exception), exception, tb=exc_tb, cause=cause)
  File "E:\GraduationWork\ENV\lib\site-packages\sqlalchemy\util\compat.py", line 152, in reraise
    raise value.with_traceback(tb)
  File "E:\GraduationWork\ENV\lib\site-packages\sqlalchemy\engine\base.py", line 1245, in _execute_context
    self.dialect.do_execute(
  File "E:\GraduationWork\ENV\lib\site-packages\sqlalchemy\engine\default.py", line 581, in do_execute
    cursor.execute(statement, parameters)
sqlalchemy.exc.OperationalError: (sqlite3.OperationalError) no such table: department
[SQL: SELECT department.id AS department_id, department.name AS department_name 
FROM department]
(Background on this error at: http://sqlalche.me/e/e3q8)
2020-02-20 14:22:06,904 - rest.api - INFO - Web-service started
2020-02-20 14:22:20,249 - service.crud - DEBUG - Department 10001 was returned
2020-02-20 14:28:06,199 - rest.api - INFO - Web-service started
2020-02-20 14:28:33,404 - service.crud - DEBUG - List of department was returned
2020-02-20 14:33:28,614 - rest.api - INFO - Web-service started
2020-02-20 14:33:40,125 - service.crud - DEBUG - Employee was updated
2020-02-20 14:36:53,194 - rest.api - INFO - Web-service started
2020-02-20 14:37:11,584 - service.crud - DEBUG - List of department was returned
2020-02-20 14:37:34,634 - rest.api - INFO - Web-service started
2020-02-20 14:37:44,125 - service.crud - DEBUG - Department 10001 was updated
2020-02-20 17:13:47,463 - rest.api - INFO - Web-service started
2020-02-20 17:20:00,033 - rest.api - INFO - Web-service started
2020-02-20 17:20:08,020 - rest.api - INFO - Web-service started
2020-02-20 17:23:48,497 - rest.api - INFO - Web-service started
2020-02-20 17:24:24,503 - rest.api - INFO - Web-service started
2020-02-20 17:24:30,374 - service.crud - DEBUG - Department 10002 was added
2020-02-20 17:28:01,143 - rest.api - INFO - Web-service started
2020-02-20 17:29:34,283 - rest.api - INFO - Web-service started
2020-02-20 17:30:19,644 - rest.api - INFO - Web-service started
2020-02-20 17:30:22,627 - service.crud - DEBUG - Department 10001 was updated
2020-02-20 17:30:30,344 - rest.api - INFO - Web-service started
2020-02-20 17:30:33,354 - service.crud - DEBUG - Department 10002 was added
2020-02-20 17:30:36,575 - service.crud - DEBUG - Department 10001 was deleted
2020-02-20 17:30:36,714 - service.crud - DEBUG - Department 10001 is not exist
2020-02-20 17:30:39,954 - service.crud - DEBUG - Department 10001 was returned
2020-02-20 17:30:43,395 - service.crud - DEBUG - List of department was returned
2020-02-20 17:30:46,534 - service.crud - DEBUG - Department 10001 was updated
2020-02-20 17:32:03,767 - rest.api - INFO - Web-service started
2020-02-20 17:32:10,735 - service.crud - DEBUG - Employee was added
2020-02-20 17:32:17,106 - service.crud - DEBUG - Employee 1 is not exist
2020-02-20 17:32:25,764 - service.crud - DEBUG - Employee 1 was returned
2020-02-20 17:32:29,874 - service.crud - DEBUG - List of employees was returned
2020-02-20 17:32:36,604 - service.crud - DEBUG - Filtered by dates list of employees was returned
2020-02-20 17:32:36,903 - service.crud - DEBUG - Filtered by dates list of employees was returned
2020-02-20 17:32:43,779 - service.crud - DEBUG - Employee was updated
2020-02-20 17:51:30,657 - rest.api - INFO - Web-service started
2020-02-20 17:52:53,290 - rest.api - INFO - Web-service started
2020-02-20 17:52:57,263 - rest.api - DEBUG - POST method (/api/department) was not successful (400)
2020-02-20 17:53:38,835 - rest.api - INFO - Web-service started
2020-02-20 17:54:03,081 - rest.api - INFO - Web-service started
2020-02-20 17:54:06,975 - service.crud - DEBUG - List of employees was returned
2020-02-20 17:54:07,144 - rest.api - DEBUG - GET method (/api/employees) was successful
2020-02-20 17:54:19,718 - rest.api - INFO - Web-service started
2020-02-20 17:54:35,409 - rest.api - INFO - Web-service started
2020-02-20 17:54:39,528 - service.crud - DEBUG - List of department was returned
2020-02-20 17:56:06,104 - rest.api - INFO - Web-service started
2020-02-20 17:56:09,750 - service.crud - DEBUG - List of department was returned
2020-02-20 17:56:09,911 - rest.api - DEBUG - GET method (/api/departments) was successful
2020-02-20 17:57:59,331 - rest.api - INFO - Web-service started
2020-02-20 17:58:05,141 - rest.api - INFO - Web-service started
2020-02-20 17:58:13,890 - rest.api - INFO - Web-service started
2020-02-20 17:58:25,088 - rest.api - INFO - Web-service started
2020-02-20 17:58:30,001 - service.crud - DEBUG - List of department was returned
2020-02-20 17:58:30,309 - rest.api - DEBUG - GET method (/api/departments) was successful
2020-02-20 17:59:04,878 - rest.api - INFO - Web-service started
2020-02-20 17:59:10,464 - rest.api - INFO - Web-service started
2020-02-20 17:59:15,069 - rest.api - INFO - Web-service started
2020-02-20 17:59:20,821 - service.crud - DEBUG - List of department was returned
2020-02-20 17:59:20,985 - rest.api - DEBUG - GET method (/api/departments) was successful
2020-02-20 18:09:55,196 - rest.api - INFO - Web-service started
2020-02-20 18:09:58,793 - rest.api - DEBUG - POST method (/api/department) was not successful (400)
2020-02-20 18:10:59,699 - rest.api - INFO - Web-service started
2020-02-20 18:11:03,507 - service.crud - DEBUG - Department 10002 was added
2020-02-20 18:11:03,507 - rest.api - DEBUG - POST method (/api/department) was successful
2020-02-20 18:11:44,411 - rest.api - INFO - Web-service started
2020-02-20 18:11:48,045 - service.crud - DEBUG - Department 10002 was added
2020-02-20 18:11:48,045 - rest.api - DEBUG - POST method (/api/department) was successful
2020-02-20 18:13:16,626 - rest.api - INFO - Web-service started
2020-02-20 18:13:23,007 - service.crud - DEBUG - Department 10002 was added
2020-02-20 18:13:23,008 - rest.api - DEBUG - POST method (/api/department) was successful
2020-02-20 18:13:30,413 - rest.api - INFO - Web-service started
2020-02-20 18:13:34,568 - rest.api - DEBUG - POST method (/api/department) was not successful (400)
2020-02-20 18:13:34,979 - service.crud - DEBUG - Department some string was added
2020-02-20 18:13:34,979 - rest.api - DEBUG - POST method (/api/department) was successful
2020-02-20 18:24:11,507 - rest.api - INFO - Web-service started
2020-02-20 18:24:30,154 - rest.api - INFO - Web-service started
2020-02-20 18:24:34,741 - rest.api - INFO - Web-service started
2020-02-20 18:24:51,800 - rest.api - INFO - Web-service started
2020-02-20 18:24:56,257 - rest.api - INFO - Web-service started
2020-02-20 18:25:02,411 - service.crud - DEBUG - Department 10001 was returned
2020-02-20 18:25:02,574 - rest.api - DEBUG - GET method (/api/department/10001) was successful
2020-02-20 18:25:15,535 - rest.api - INFO - Web-service started
2020-02-20 18:25:18,426 - service.crud - DEBUG - Department 10005 is not exist
2020-02-20 18:25:18,426 - rest.api - DEBUG - GET method (/api/department/10005) was not successful (404)
2020-02-20 18:28:02,700 - rest.api - INFO - Web-service started
2020-02-20 18:28:06,538 - service.crud - DEBUG - Department 10001 was updated
2020-02-20 18:28:07,576 - rest.api - DEBUG - PUT method (/api/department/10001) was successful
2020-02-20 18:29:11,920 - rest.api - INFO - Web-service started
2020-02-20 18:29:16,379 - service.crud - DEBUG - Department 10005 is not exist, it can`t be updated
2020-02-20 18:29:16,379 - rest.api - DEBUG - PUT method (/api/department/10005) was not successful (404)
2020-02-20 22:02:12,309 - rest.api - INFO - Web-service started
2020-02-20 22:02:16,325 - service.crud - DEBUG - List of employees was returned
2020-02-20 22:02:16,506 - rest.api - DEBUG - GET method (/api/employees) was successful
2020-02-20 22:07:53,284 - rest.api - INFO - Web-service started
2020-02-20 22:07:56,629 - service.crud - DEBUG - Filtered by dates list of employees was returned
2020-02-20 22:08:58,334 - rest.api - INFO - Web-service started
2020-02-20 22:09:08,181 - rest.api - INFO - Web-service started
2020-02-20 22:09:11,642 - service.crud - DEBUG - Filtered by dates list of employees was returned
2020-02-20 22:09:31,216 - rest.api - INFO - Web-service started
2020-02-20 22:09:36,654 - service.crud - DEBUG - Filtered by dates list of employees was returned
2020-02-20 22:10:41,759 - rest.api - INFO - Web-service started
2020-02-20 22:10:44,603 - service.crud - DEBUG - Filtered by dates list of employees was returned
2020-02-20 22:10:44,746 - rest.api - DEBUG - POST method (/api/employees) was successful
2020-02-20 22:10:44,798 - service.crud - DEBUG - Filtered by dates list of employees was returned
2020-02-20 22:10:44,940 - rest.api - DEBUG - POST method (/api/employees) was successful
2020-02-20 22:11:08,086 - rest.api - INFO - Web-service started
2020-02-20 22:11:11,511 - service.crud - DEBUG - Filtered by dates list of employees was returned
2020-02-20 22:11:11,800 - rest.api - DEBUG - POST method (/api/employees) was successful
2020-02-20 22:11:11,860 - service.crud - DEBUG - Filtered by dates list of employees was returned
2020-02-20 22:11:12,028 - rest.api - DEBUG - POST method (/api/employees) was successful
2020-02-20 22:14:51,753 - rest.api - INFO - Web-service started
2020-02-20 22:14:55,104 - service.crud - DEBUG - Filtered by dates list of employees was returned
2020-02-20 22:14:55,273 - rest.api - DEBUG - POST method (/api/employees) was successful
2020-02-20 22:14:55,327 - service.crud - DEBUG - Filtered by dates list of employees was returned
2020-02-20 22:14:55,495 - rest.api - DEBUG - POST method (/api/employees) was successful
2020-02-20 22:15:33,197 - rest.api - INFO - Web-service started
2020-02-20 22:15:35,884 - service.crud - DEBUG - Filtered by dates list of employees was returned
2020-02-20 22:15:36,019 - rest.api - DEBUG - POST method (/api/employees) was successful
2020-02-20 22:15:36,069 - service.crud - DEBUG - Filtered by dates list of employees was returned
2020-02-20 22:15:36,202 - rest.api - DEBUG - POST method (/api/employees) was successful
2020-02-20 22:15:36,253 - service.crud - DEBUG - Filtered by dates list of employees was returned
2020-02-20 22:15:36,390 - rest.api - DEBUG - POST method (/api/employees) was successful
2020-02-20 22:17:19,764 - rest.api - INFO - Web-service started
2020-02-20 22:17:24,421 - rest.api - INFO - Web-service started
2020-02-20 22:17:29,561 - service.crud - DEBUG - Employee was added
2020-02-20 22:17:29,716 - rest.api - DEBUG - POST method (/api/employee) was successful
2020-02-20 22:17:32,497 - service.crud - DEBUG - Department isn`t exist. Employee can`t be added
2020-02-20 22:17:32,497 - rest.api - DEBUG - POST method (/api/employee) was not successful (400)
2020-02-20 22:17:59,157 - rest.api - INFO - Web-service started
2020-02-20 22:18:04,601 - service.crud - DEBUG - Employee isn`t exist. It can`t be deleted
2020-02-20 22:18:04,601 - rest.api - DEBUG - DELETE method (/api/employee/5) was not successful (404)
2020-02-20 22:18:07,840 - service.crud - DEBUG - Employee 1 was returned
2020-02-20 22:18:07,840 - rest.api - DEBUG - GET method (/api/employee/1) was successful
2020-02-20 22:18:12,441 - service.crud - DEBUG - Employee 3 is not exist
2020-02-20 22:18:12,442 - rest.api - DEBUG - GET method (/api/employee/3) was not successful (404)
2020-02-20 22:18:17,490 - service.crud - DEBUG - Employee was updated
2020-02-20 22:18:17,491 - rest.api - DEBUG - PUT method (/api/employee/1) was successful
2020-02-20 22:18:21,565 - service.crud - DEBUG - Incorrect data. Employee can`t be updated
2020-02-20 22:18:21,565 - rest.api - DEBUG - PUT method (/api/employee/1) was not successful (400)
2020-02-20 22:18:21,791 - service.crud - DEBUG - Employee isn`t exist
2020-02-20 22:18:21,792 - rest.api - DEBUG - PUT method (/api/employee/5) was not successful (404)
2020-02-20 22:18:37,281 - rest.api - INFO - Web-service started
2020-02-20 22:18:41,952 - rest.api - DEBUG - DELETE method (/api/employee/1) was successful
2020-02-20 22:18:45,035 - service.crud - DEBUG - Employee isn`t exist. It can`t be deleted
2020-02-20 22:18:45,036 - rest.api - DEBUG - DELETE method (/api/employee/5) was not successful (404)
2020-02-20 22:18:48,641 - service.crud - DEBUG - Employee 1 was returned
2020-02-20 22:18:48,641 - rest.api - DEBUG - GET method (/api/employee/1) was successful
2020-02-20 22:18:52,187 - service.crud - DEBUG - Employee 3 is not exist
2020-02-20 22:18:52,187 - rest.api - DEBUG - GET method (/api/employee/3) was not successful (404)
2020-02-20 22:18:55,833 - service.crud - DEBUG - Employee was updated
2020-02-20 22:18:55,833 - rest.api - DEBUG - PUT method (/api/employee/1) was successful
2020-02-20 22:19:00,482 - service.crud - DEBUG - Incorrect data. Employee can`t be updated
2020-02-20 22:19:00,483 - rest.api - DEBUG - PUT method (/api/employee/1) was not successful (400)
2020-02-20 22:19:00,864 - service.crud - DEBUG - Employee isn`t exist
2020-02-20 22:19:00,864 - rest.api - DEBUG - PUT method (/api/employee/5) was not successful (404)
2020-02-22 22:45:47,392 - rest.api - INFO - Web-service started
2020-02-22 22:45:56,223 - rest.api - ERROR - Exception on /api/departments [GET]
Traceback (most recent call last):
  File "E:\GraduationWork\ENV\lib\site-packages\sqlalchemy\engine\base.py", line 1245, in _execute_context
    self.dialect.do_execute(
  File "E:\GraduationWork\ENV\lib\site-packages\sqlalchemy\engine\default.py", line 581, in do_execute
    cursor.execute(statement, parameters)
  File "E:\GraduationWork\ENV\lib\site-packages\mysql\connector\cursor.py", line 551, in execute
    self._handle_result(self._connection.cmd_query(stmt))
  File "E:\GraduationWork\ENV\lib\site-packages\mysql\connector\connection.py", line 490, in cmd_query
    result = self._handle_result(self._send_cmd(ServerCmd.QUERY, query))
  File "E:\GraduationWork\ENV\lib\site-packages\mysql\connector\connection.py", line 395, in _handle_result
    raise errors.get_exception(packet)
mysql.connector.errors.ProgrammingError: 1146 (42S02): Table 'sql7323829.department' doesn't exist

The above exception was the direct cause of the following exception:

Traceback (most recent call last):
  File "E:\GraduationWork\ENV\lib\site-packages\flask\app.py", line 1949, in full_dispatch_request
    rv = self.dispatch_request()
  File "E:\GraduationWork\ENV\lib\site-packages\flask\app.py", line 1935, in dispatch_request
    return self.view_functions[rule.endpoint](**req.view_args)
  File "E:\GraduationWork\ENV\lib\site-packages\flask_restful\__init__.py", line 458, in wrapper
    resp = resource(*args, **kwargs)
  File "E:\GraduationWork\ENV\lib\site-packages\flask\views.py", line 89, in view
    return self.dispatch_request(*args, **kwargs)
  File "E:\GraduationWork\ENV\lib\site-packages\flask_restful\__init__.py", line 573, in dispatch_request
    resp = meth(*args, **kwargs)
  File "E:\GraduationWork\DepartmentHandler\department-app\rest\api.py", line 50, in get
    data = crud.Departments.get_all()
  File "E:\GraduationWork\DepartmentHandler\department-app\service\crud.py", line 32, in get_all
    departments = Department.query.all()
  File "E:\GraduationWork\ENV\lib\site-packages\sqlalchemy\orm\query.py", line 3211, in all
    return list(self)
  File "E:\GraduationWork\ENV\lib\site-packages\sqlalchemy\orm\query.py", line 3367, in __iter__
    return self._execute_and_instances(context)
  File "E:\GraduationWork\ENV\lib\site-packages\sqlalchemy\orm\query.py", line 3392, in _execute_and_instances
    result = conn.execute(querycontext.statement, self._params)
  File "E:\GraduationWork\ENV\lib\site-packages\sqlalchemy\engine\base.py", line 982, in execute
    return meth(self, multiparams, params)
  File "E:\GraduationWork\ENV\lib\site-packages\sqlalchemy\sql\elements.py", line 287, in _execute_on_connection
    return connection._execute_clauseelement(self, multiparams, params)
  File "E:\GraduationWork\ENV\lib\site-packages\sqlalchemy\engine\base.py", line 1095, in _execute_clauseelement
    ret = self._execute_context(
  File "E:\GraduationWork\ENV\lib\site-packages\sqlalchemy\engine\base.py", line 1249, in _execute_context
    self._handle_dbapi_exception(
  File "E:\GraduationWork\ENV\lib\site-packages\sqlalchemy\engine\base.py", line 1476, in _handle_dbapi_exception
    util.raise_from_cause(sqlalchemy_exception, exc_info)
  File "E:\GraduationWork\ENV\lib\site-packages\sqlalchemy\util\compat.py", line 398, in raise_from_cause
    reraise(type(exception), exception, tb=exc_tb, cause=cause)
  File "E:\GraduationWork\ENV\lib\site-packages\sqlalchemy\util\compat.py", line 152, in reraise
    raise value.with_traceback(tb)
  File "E:\GraduationWork\ENV\lib\site-packages\sqlalchemy\engine\base.py", line 1245, in _execute_context
    self.dialect.do_execute(
  File "E:\GraduationWork\ENV\lib\site-packages\sqlalchemy\engine\default.py", line 581, in do_execute
    cursor.execute(statement, parameters)
  File "E:\GraduationWork\ENV\lib\site-packages\mysql\connector\cursor.py", line 551, in execute
    self._handle_result(self._connection.cmd_query(stmt))
  File "E:\GraduationWork\ENV\lib\site-packages\mysql\connector\connection.py", line 490, in cmd_query
    result = self._handle_result(self._send_cmd(ServerCmd.QUERY, query))
  File "E:\GraduationWork\ENV\lib\site-packages\mysql\connector\connection.py", line 395, in _handle_result
    raise errors.get_exception(packet)
sqlalchemy.exc.ProgrammingError: (mysql.connector.errors.ProgrammingError) 1146 (42S02): Table 'sql7323829.department' doesn't exist
[SQL: SELECT department.id AS department_id, department.name AS department_name 
FROM department]
(Background on this error at: http://sqlalche.me/e/f405)
2020-02-22 22:49:22,098 - rest.api - ERROR - Exception on /api/departments [GET]
Traceback (most recent call last):
  File "E:\GraduationWork\ENV\lib\site-packages\sqlalchemy\engine\base.py", line 1245, in _execute_context
    self.dialect.do_execute(
  File "E:\GraduationWork\ENV\lib\site-packages\sqlalchemy\engine\default.py", line 581, in do_execute
    cursor.execute(statement, parameters)
  File "E:\GraduationWork\ENV\lib\site-packages\mysql\connector\cursor.py", line 551, in execute
    self._handle_result(self._connection.cmd_query(stmt))
  File "E:\GraduationWork\ENV\lib\site-packages\mysql\connector\connection.py", line 490, in cmd_query
    result = self._handle_result(self._send_cmd(ServerCmd.QUERY, query))
  File "E:\GraduationWork\ENV\lib\site-packages\mysql\connector\connection.py", line 395, in _handle_result
    raise errors.get_exception(packet)
mysql.connector.errors.ProgrammingError: 1146 (42S02): Table 'sql7323829.department' doesn't exist

The above exception was the direct cause of the following exception:

Traceback (most recent call last):
  File "E:\GraduationWork\ENV\lib\site-packages\flask\app.py", line 1949, in full_dispatch_request
    rv = self.dispatch_request()
  File "E:\GraduationWork\ENV\lib\site-packages\flask\app.py", line 1935, in dispatch_request
    return self.view_functions[rule.endpoint](**req.view_args)
  File "E:\GraduationWork\ENV\lib\site-packages\flask_restful\__init__.py", line 458, in wrapper
    resp = resource(*args, **kwargs)
  File "E:\GraduationWork\ENV\lib\site-packages\flask\views.py", line 89, in view
    return self.dispatch_request(*args, **kwargs)
  File "E:\GraduationWork\ENV\lib\site-packages\flask_restful\__init__.py", line 573, in dispatch_request
    resp = meth(*args, **kwargs)
  File "E:\GraduationWork\DepartmentHandler\department-app\rest\api.py", line 50, in get
    data = crud.Departments.get_all()
  File "E:\GraduationWork\DepartmentHandler\department-app\service\crud.py", line 32, in get_all
    departments = Department.query.all()
  File "E:\GraduationWork\ENV\lib\site-packages\sqlalchemy\orm\query.py", line 3211, in all
    return list(self)
  File "E:\GraduationWork\ENV\lib\site-packages\sqlalchemy\orm\query.py", line 3367, in __iter__
    return self._execute_and_instances(context)
  File "E:\GraduationWork\ENV\lib\site-packages\sqlalchemy\orm\query.py", line 3392, in _execute_and_instances
    result = conn.execute(querycontext.statement, self._params)
  File "E:\GraduationWork\ENV\lib\site-packages\sqlalchemy\engine\base.py", line 982, in execute
    return meth(self, multiparams, params)
  File "E:\GraduationWork\ENV\lib\site-packages\sqlalchemy\sql\elements.py", line 287, in _execute_on_connection
    return connection._execute_clauseelement(self, multiparams, params)
  File "E:\GraduationWork\ENV\lib\site-packages\sqlalchemy\engine\base.py", line 1095, in _execute_clauseelement
    ret = self._execute_context(
  File "E:\GraduationWork\ENV\lib\site-packages\sqlalchemy\engine\base.py", line 1249, in _execute_context
    self._handle_dbapi_exception(
  File "E:\GraduationWork\ENV\lib\site-packages\sqlalchemy\engine\base.py", line 1476, in _handle_dbapi_exception
    util.raise_from_cause(sqlalchemy_exception, exc_info)
  File "E:\GraduationWork\ENV\lib\site-packages\sqlalchemy\util\compat.py", line 398, in raise_from_cause
    reraise(type(exception), exception, tb=exc_tb, cause=cause)
  File "E:\GraduationWork\ENV\lib\site-packages\sqlalchemy\util\compat.py", line 152, in reraise
    raise value.with_traceback(tb)
  File "E:\GraduationWork\ENV\lib\site-packages\sqlalchemy\engine\base.py", line 1245, in _execute_context
    self.dialect.do_execute(
  File "E:\GraduationWork\ENV\lib\site-packages\sqlalchemy\engine\default.py", line 581, in do_execute
    cursor.execute(statement, parameters)
  File "E:\GraduationWork\ENV\lib\site-packages\mysql\connector\cursor.py", line 551, in execute
    self._handle_result(self._connection.cmd_query(stmt))
  File "E:\GraduationWork\ENV\lib\site-packages\mysql\connector\connection.py", line 490, in cmd_query
    result = self._handle_result(self._send_cmd(ServerCmd.QUERY, query))
  File "E:\GraduationWork\ENV\lib\site-packages\mysql\connector\connection.py", line 395, in _handle_result
    raise errors.get_exception(packet)
sqlalchemy.exc.ProgrammingError: (mysql.connector.errors.ProgrammingError) 1146 (42S02): Table 'sql7323829.department' doesn't exist
[SQL: SELECT department.id AS department_id, department.name AS department_name 
FROM department]
(Background on this error at: http://sqlalche.me/e/f405)
2020-02-22 22:49:40,240 - rest.api - ERROR - Exception on /api/departments [GET]
Traceback (most recent call last):
  File "E:\GraduationWork\ENV\lib\site-packages\sqlalchemy\engine\base.py", line 1245, in _execute_context
    self.dialect.do_execute(
  File "E:\GraduationWork\ENV\lib\site-packages\sqlalchemy\engine\default.py", line 581, in do_execute
    cursor.execute(statement, parameters)
  File "E:\GraduationWork\ENV\lib\site-packages\mysql\connector\cursor.py", line 551, in execute
    self._handle_result(self._connection.cmd_query(stmt))
  File "E:\GraduationWork\ENV\lib\site-packages\mysql\connector\connection.py", line 490, in cmd_query
    result = self._handle_result(self._send_cmd(ServerCmd.QUERY, query))
  File "E:\GraduationWork\ENV\lib\site-packages\mysql\connector\connection.py", line 395, in _handle_result
    raise errors.get_exception(packet)
mysql.connector.errors.ProgrammingError: 1146 (42S02): Table 'sql7323829.department' doesn't exist

The above exception was the direct cause of the following exception:

Traceback (most recent call last):
  File "E:\GraduationWork\ENV\lib\site-packages\flask\app.py", line 1949, in full_dispatch_request
    rv = self.dispatch_request()
  File "E:\GraduationWork\ENV\lib\site-packages\flask\app.py", line 1935, in dispatch_request
    return self.view_functions[rule.endpoint](**req.view_args)
  File "E:\GraduationWork\ENV\lib\site-packages\flask_restful\__init__.py", line 458, in wrapper
    resp = resource(*args, **kwargs)
  File "E:\GraduationWork\ENV\lib\site-packages\flask\views.py", line 89, in view
    return self.dispatch_request(*args, **kwargs)
  File "E:\GraduationWork\ENV\lib\site-packages\flask_restful\__init__.py", line 573, in dispatch_request
    resp = meth(*args, **kwargs)
  File "E:\GraduationWork\DepartmentHandler\department-app\rest\api.py", line 50, in get
    data = crud.Departments.get_all()
  File "E:\GraduationWork\DepartmentHandler\department-app\service\crud.py", line 32, in get_all
    departments = Department.query.all()
  File "E:\GraduationWork\ENV\lib\site-packages\sqlalchemy\orm\query.py", line 3211, in all
    return list(self)
  File "E:\GraduationWork\ENV\lib\site-packages\sqlalchemy\orm\query.py", line 3367, in __iter__
    return self._execute_and_instances(context)
  File "E:\GraduationWork\ENV\lib\site-packages\sqlalchemy\orm\query.py", line 3392, in _execute_and_instances
    result = conn.execute(querycontext.statement, self._params)
  File "E:\GraduationWork\ENV\lib\site-packages\sqlalchemy\engine\base.py", line 982, in execute
    return meth(self, multiparams, params)
  File "E:\GraduationWork\ENV\lib\site-packages\sqlalchemy\sql\elements.py", line 287, in _execute_on_connection
    return connection._execute_clauseelement(self, multiparams, params)
  File "E:\GraduationWork\ENV\lib\site-packages\sqlalchemy\engine\base.py", line 1095, in _execute_clauseelement
    ret = self._execute_context(
  File "E:\GraduationWork\ENV\lib\site-packages\sqlalchemy\engine\base.py", line 1249, in _execute_context
    self._handle_dbapi_exception(
  File "E:\GraduationWork\ENV\lib\site-packages\sqlalchemy\engine\base.py", line 1476, in _handle_dbapi_exception
    util.raise_from_cause(sqlalchemy_exception, exc_info)
  File "E:\GraduationWork\ENV\lib\site-packages\sqlalchemy\util\compat.py", line 398, in raise_from_cause
    reraise(type(exception), exception, tb=exc_tb, cause=cause)
  File "E:\GraduationWork\ENV\lib\site-packages\sqlalchemy\util\compat.py", line 152, in reraise
    raise value.with_traceback(tb)
  File "E:\GraduationWork\ENV\lib\site-packages\sqlalchemy\engine\base.py", line 1245, in _execute_context
    self.dialect.do_execute(
  File "E:\GraduationWork\ENV\lib\site-packages\sqlalchemy\engine\default.py", line 581, in do_execute
    cursor.execute(statement, parameters)
  File "E:\GraduationWork\ENV\lib\site-packages\mysql\connector\cursor.py", line 551, in execute
    self._handle_result(self._connection.cmd_query(stmt))
  File "E:\GraduationWork\ENV\lib\site-packages\mysql\connector\connection.py", line 490, in cmd_query
    result = self._handle_result(self._send_cmd(ServerCmd.QUERY, query))
  File "E:\GraduationWork\ENV\lib\site-packages\mysql\connector\connection.py", line 395, in _handle_result
    raise errors.get_exception(packet)
sqlalchemy.exc.ProgrammingError: (mysql.connector.errors.ProgrammingError) 1146 (42S02): Table 'sql7323829.department' doesn't exist
[SQL: SELECT department.id AS department_id, department.name AS department_name 
FROM department]
(Background on this error at: http://sqlalche.me/e/f405)
2020-02-22 22:51:09,863 - rest.api - ERROR - Exception on /api/departments [GET]
Traceback (most recent call last):
  File "E:\GraduationWork\ENV\lib\site-packages\sqlalchemy\engine\base.py", line 1245, in _execute_context
    self.dialect.do_execute(
  File "E:\GraduationWork\ENV\lib\site-packages\sqlalchemy\engine\default.py", line 581, in do_execute
    cursor.execute(statement, parameters)
  File "E:\GraduationWork\ENV\lib\site-packages\mysql\connector\cursor.py", line 551, in execute
    self._handle_result(self._connection.cmd_query(stmt))
  File "E:\GraduationWork\ENV\lib\site-packages\mysql\connector\connection.py", line 490, in cmd_query
    result = self._handle_result(self._send_cmd(ServerCmd.QUERY, query))
  File "E:\GraduationWork\ENV\lib\site-packages\mysql\connector\connection.py", line 395, in _handle_result
    raise errors.get_exception(packet)
mysql.connector.errors.ProgrammingError: 1146 (42S02): Table 'sql7323829.department' doesn't exist

The above exception was the direct cause of the following exception:

Traceback (most recent call last):
  File "E:\GraduationWork\ENV\lib\site-packages\flask\app.py", line 1949, in full_dispatch_request
    rv = self.dispatch_request()
  File "E:\GraduationWork\ENV\lib\site-packages\flask\app.py", line 1935, in dispatch_request
    return self.view_functions[rule.endpoint](**req.view_args)
  File "E:\GraduationWork\ENV\lib\site-packages\flask_restful\__init__.py", line 458, in wrapper
    resp = resource(*args, **kwargs)
  File "E:\GraduationWork\ENV\lib\site-packages\flask\views.py", line 89, in view
    return self.dispatch_request(*args, **kwargs)
  File "E:\GraduationWork\ENV\lib\site-packages\flask_restful\__init__.py", line 573, in dispatch_request
    resp = meth(*args, **kwargs)
  File "E:\GraduationWork\DepartmentHandler\department-app\rest\api.py", line 50, in get
    data = crud.Departments.get_all()
  File "E:\GraduationWork\DepartmentHandler\department-app\service\crud.py", line 32, in get_all
    departments = Department.query.all()
  File "E:\GraduationWork\ENV\lib\site-packages\sqlalchemy\orm\query.py", line 3211, in all
    return list(self)
  File "E:\GraduationWork\ENV\lib\site-packages\sqlalchemy\orm\query.py", line 3367, in __iter__
    return self._execute_and_instances(context)
  File "E:\GraduationWork\ENV\lib\site-packages\sqlalchemy\orm\query.py", line 3392, in _execute_and_instances
    result = conn.execute(querycontext.statement, self._params)
  File "E:\GraduationWork\ENV\lib\site-packages\sqlalchemy\engine\base.py", line 982, in execute
    return meth(self, multiparams, params)
  File "E:\GraduationWork\ENV\lib\site-packages\sqlalchemy\sql\elements.py", line 287, in _execute_on_connection
    return connection._execute_clauseelement(self, multiparams, params)
  File "E:\GraduationWork\ENV\lib\site-packages\sqlalchemy\engine\base.py", line 1095, in _execute_clauseelement
    ret = self._execute_context(
  File "E:\GraduationWork\ENV\lib\site-packages\sqlalchemy\engine\base.py", line 1249, in _execute_context
    self._handle_dbapi_exception(
  File "E:\GraduationWork\ENV\lib\site-packages\sqlalchemy\engine\base.py", line 1476, in _handle_dbapi_exception
    util.raise_from_cause(sqlalchemy_exception, exc_info)
  File "E:\GraduationWork\ENV\lib\site-packages\sqlalchemy\util\compat.py", line 398, in raise_from_cause
    reraise(type(exception), exception, tb=exc_tb, cause=cause)
  File "E:\GraduationWork\ENV\lib\site-packages\sqlalchemy\util\compat.py", line 152, in reraise
    raise value.with_traceback(tb)
  File "E:\GraduationWork\ENV\lib\site-packages\sqlalchemy\engine\base.py", line 1245, in _execute_context
    self.dialect.do_execute(
  File "E:\GraduationWork\ENV\lib\site-packages\sqlalchemy\engine\default.py", line 581, in do_execute
    cursor.execute(statement, parameters)
  File "E:\GraduationWork\ENV\lib\site-packages\mysql\connector\cursor.py", line 551, in execute
    self._handle_result(self._connection.cmd_query(stmt))
  File "E:\GraduationWork\ENV\lib\site-packages\mysql\connector\connection.py", line 490, in cmd_query
    result = self._handle_result(self._send_cmd(ServerCmd.QUERY, query))
  File "E:\GraduationWork\ENV\lib\site-packages\mysql\connector\connection.py", line 395, in _handle_result
    raise errors.get_exception(packet)
sqlalchemy.exc.ProgrammingError: (mysql.connector.errors.ProgrammingError) 1146 (42S02): Table 'sql7323829.department' doesn't exist
[SQL: SELECT department.id AS department_id, department.name AS department_name 
FROM department]
(Background on this error at: http://sqlalche.me/e/f405)
2020-02-22 22:52:10,450 - rest.api - ERROR - Exception on /api/departments [GET]
Traceback (most recent call last):
  File "E:\GraduationWork\ENV\lib\site-packages\sqlalchemy\engine\base.py", line 1245, in _execute_context
    self.dialect.do_execute(
  File "E:\GraduationWork\ENV\lib\site-packages\sqlalchemy\engine\default.py", line 581, in do_execute
    cursor.execute(statement, parameters)
  File "E:\GraduationWork\ENV\lib\site-packages\mysql\connector\cursor.py", line 551, in execute
    self._handle_result(self._connection.cmd_query(stmt))
  File "E:\GraduationWork\ENV\lib\site-packages\mysql\connector\connection.py", line 490, in cmd_query
    result = self._handle_result(self._send_cmd(ServerCmd.QUERY, query))
  File "E:\GraduationWork\ENV\lib\site-packages\mysql\connector\connection.py", line 395, in _handle_result
    raise errors.get_exception(packet)
mysql.connector.errors.ProgrammingError: 1146 (42S02): Table 'sql7323829.department' doesn't exist

The above exception was the direct cause of the following exception:

Traceback (most recent call last):
  File "E:\GraduationWork\ENV\lib\site-packages\flask\app.py", line 1949, in full_dispatch_request
    rv = self.dispatch_request()
  File "E:\GraduationWork\ENV\lib\site-packages\flask\app.py", line 1935, in dispatch_request
    return self.view_functions[rule.endpoint](**req.view_args)
  File "E:\GraduationWork\ENV\lib\site-packages\flask_restful\__init__.py", line 458, in wrapper
    resp = resource(*args, **kwargs)
  File "E:\GraduationWork\ENV\lib\site-packages\flask\views.py", line 89, in view
    return self.dispatch_request(*args, **kwargs)
  File "E:\GraduationWork\ENV\lib\site-packages\flask_restful\__init__.py", line 573, in dispatch_request
    resp = meth(*args, **kwargs)
  File "E:\GraduationWork\DepartmentHandler\department-app\rest\api.py", line 50, in get
    data = crud.Departments.get_all()
  File "E:\GraduationWork\DepartmentHandler\department-app\service\crud.py", line 32, in get_all
    departments = Department.query.all()
  File "E:\GraduationWork\ENV\lib\site-packages\sqlalchemy\orm\query.py", line 3211, in all
    return list(self)
  File "E:\GraduationWork\ENV\lib\site-packages\sqlalchemy\orm\query.py", line 3367, in __iter__
    return self._execute_and_instances(context)
  File "E:\GraduationWork\ENV\lib\site-packages\sqlalchemy\orm\query.py", line 3392, in _execute_and_instances
    result = conn.execute(querycontext.statement, self._params)
  File "E:\GraduationWork\ENV\lib\site-packages\sqlalchemy\engine\base.py", line 982, in execute
    return meth(self, multiparams, params)
  File "E:\GraduationWork\ENV\lib\site-packages\sqlalchemy\sql\elements.py", line 287, in _execute_on_connection
    return connection._execute_clauseelement(self, multiparams, params)
  File "E:\GraduationWork\ENV\lib\site-packages\sqlalchemy\engine\base.py", line 1095, in _execute_clauseelement
    ret = self._execute_context(
  File "E:\GraduationWork\ENV\lib\site-packages\sqlalchemy\engine\base.py", line 1249, in _execute_context
    self._handle_dbapi_exception(
  File "E:\GraduationWork\ENV\lib\site-packages\sqlalchemy\engine\base.py", line 1476, in _handle_dbapi_exception
    util.raise_from_cause(sqlalchemy_exception, exc_info)
  File "E:\GraduationWork\ENV\lib\site-packages\sqlalchemy\util\compat.py", line 398, in raise_from_cause
    reraise(type(exception), exception, tb=exc_tb, cause=cause)
  File "E:\GraduationWork\ENV\lib\site-packages\sqlalchemy\util\compat.py", line 152, in reraise
    raise value.with_traceback(tb)
  File "E:\GraduationWork\ENV\lib\site-packages\sqlalchemy\engine\base.py", line 1245, in _execute_context
    self.dialect.do_execute(
  File "E:\GraduationWork\ENV\lib\site-packages\sqlalchemy\engine\default.py", line 581, in do_execute
    cursor.execute(statement, parameters)
  File "E:\GraduationWork\ENV\lib\site-packages\mysql\connector\cursor.py", line 551, in execute
    self._handle_result(self._connection.cmd_query(stmt))
  File "E:\GraduationWork\ENV\lib\site-packages\mysql\connector\connection.py", line 490, in cmd_query
    result = self._handle_result(self._send_cmd(ServerCmd.QUERY, query))
  File "E:\GraduationWork\ENV\lib\site-packages\mysql\connector\connection.py", line 395, in _handle_result
    raise errors.get_exception(packet)
sqlalchemy.exc.ProgrammingError: (mysql.connector.errors.ProgrammingError) 1146 (42S02): Table 'sql7323829.department' doesn't exist
[SQL: SELECT department.id AS department_id, department.name AS department_name 
FROM department]
(Background on this error at: http://sqlalche.me/e/f405)
2020-02-22 22:53:26,987 - rest.api - ERROR - Exception on /api/departments [GET]
Traceback (most recent call last):
  File "E:\GraduationWork\ENV\lib\site-packages\sqlalchemy\engine\base.py", line 1245, in _execute_context
    self.dialect.do_execute(
  File "E:\GraduationWork\ENV\lib\site-packages\sqlalchemy\engine\default.py", line 581, in do_execute
    cursor.execute(statement, parameters)
  File "E:\GraduationWork\ENV\lib\site-packages\mysql\connector\cursor.py", line 551, in execute
    self._handle_result(self._connection.cmd_query(stmt))
  File "E:\GraduationWork\ENV\lib\site-packages\mysql\connector\connection.py", line 490, in cmd_query
    result = self._handle_result(self._send_cmd(ServerCmd.QUERY, query))
  File "E:\GraduationWork\ENV\lib\site-packages\mysql\connector\connection.py", line 395, in _handle_result
    raise errors.get_exception(packet)
mysql.connector.errors.ProgrammingError: 1146 (42S02): Table 'sql7323829.department' doesn't exist

The above exception was the direct cause of the following exception:

Traceback (most recent call last):
  File "E:\GraduationWork\ENV\lib\site-packages\flask\app.py", line 1949, in full_dispatch_request
    rv = self.dispatch_request()
  File "E:\GraduationWork\ENV\lib\site-packages\flask\app.py", line 1935, in dispatch_request
    return self.view_functions[rule.endpoint](**req.view_args)
  File "E:\GraduationWork\ENV\lib\site-packages\flask_restful\__init__.py", line 458, in wrapper
    resp = resource(*args, **kwargs)
  File "E:\GraduationWork\ENV\lib\site-packages\flask\views.py", line 89, in view
    return self.dispatch_request(*args, **kwargs)
  File "E:\GraduationWork\ENV\lib\site-packages\flask_restful\__init__.py", line 573, in dispatch_request
    resp = meth(*args, **kwargs)
  File "E:\GraduationWork\DepartmentHandler\department-app\rest\api.py", line 50, in get
    data = crud.Departments.get_all()
  File "E:\GraduationWork\DepartmentHandler\department-app\service\crud.py", line 32, in get_all
    departments = Department.query.all()
  File "E:\GraduationWork\ENV\lib\site-packages\sqlalchemy\orm\query.py", line 3211, in all
    return list(self)
  File "E:\GraduationWork\ENV\lib\site-packages\sqlalchemy\orm\query.py", line 3367, in __iter__
    return self._execute_and_instances(context)
  File "E:\GraduationWork\ENV\lib\site-packages\sqlalchemy\orm\query.py", line 3392, in _execute_and_instances
    result = conn.execute(querycontext.statement, self._params)
  File "E:\GraduationWork\ENV\lib\site-packages\sqlalchemy\engine\base.py", line 982, in execute
    return meth(self, multiparams, params)
  File "E:\GraduationWork\ENV\lib\site-packages\sqlalchemy\sql\elements.py", line 287, in _execute_on_connection
    return connection._execute_clauseelement(self, multiparams, params)
  File "E:\GraduationWork\ENV\lib\site-packages\sqlalchemy\engine\base.py", line 1095, in _execute_clauseelement
    ret = self._execute_context(
  File "E:\GraduationWork\ENV\lib\site-packages\sqlalchemy\engine\base.py", line 1249, in _execute_context
    self._handle_dbapi_exception(
  File "E:\GraduationWork\ENV\lib\site-packages\sqlalchemy\engine\base.py", line 1476, in _handle_dbapi_exception
    util.raise_from_cause(sqlalchemy_exception, exc_info)
  File "E:\GraduationWork\ENV\lib\site-packages\sqlalchemy\util\compat.py", line 398, in raise_from_cause
    reraise(type(exception), exception, tb=exc_tb, cause=cause)
  File "E:\GraduationWork\ENV\lib\site-packages\sqlalchemy\util\compat.py", line 152, in reraise
    raise value.with_traceback(tb)
  File "E:\GraduationWork\ENV\lib\site-packages\sqlalchemy\engine\base.py", line 1245, in _execute_context
    self.dialect.do_execute(
  File "E:\GraduationWork\ENV\lib\site-packages\sqlalchemy\engine\default.py", line 581, in do_execute
    cursor.execute(statement, parameters)
  File "E:\GraduationWork\ENV\lib\site-packages\mysql\connector\cursor.py", line 551, in execute
    self._handle_result(self._connection.cmd_query(stmt))
  File "E:\GraduationWork\ENV\lib\site-packages\mysql\connector\connection.py", line 490, in cmd_query
    result = self._handle_result(self._send_cmd(ServerCmd.QUERY, query))
  File "E:\GraduationWork\ENV\lib\site-packages\mysql\connector\connection.py", line 395, in _handle_result
    raise errors.get_exception(packet)
sqlalchemy.exc.ProgrammingError: (mysql.connector.errors.ProgrammingError) 1146 (42S02): Table 'sql7323829.department' doesn't exist
[SQL: SELECT department.id AS department_id, department.name AS department_name 
FROM department]
(Background on this error at: http://sqlalche.me/e/f405)
2020-02-22 22:53:55,102 - rest.api - ERROR - Exception on /api/departments [GET]
Traceback (most recent call last):
  File "E:\GraduationWork\ENV\lib\site-packages\sqlalchemy\engine\base.py", line 1245, in _execute_context
    self.dialect.do_execute(
  File "E:\GraduationWork\ENV\lib\site-packages\sqlalchemy\engine\default.py", line 581, in do_execute
    cursor.execute(statement, parameters)
  File "E:\GraduationWork\ENV\lib\site-packages\mysql\connector\cursor.py", line 551, in execute
    self._handle_result(self._connection.cmd_query(stmt))
  File "E:\GraduationWork\ENV\lib\site-packages\mysql\connector\connection.py", line 490, in cmd_query
    result = self._handle_result(self._send_cmd(ServerCmd.QUERY, query))
  File "E:\GraduationWork\ENV\lib\site-packages\mysql\connector\connection.py", line 395, in _handle_result
    raise errors.get_exception(packet)
mysql.connector.errors.ProgrammingError: 1146 (42S02): Table 'sql7323829.department' doesn't exist

The above exception was the direct cause of the following exception:

Traceback (most recent call last):
  File "E:\GraduationWork\ENV\lib\site-packages\flask\app.py", line 1949, in full_dispatch_request
    rv = self.dispatch_request()
  File "E:\GraduationWork\ENV\lib\site-packages\flask\app.py", line 1935, in dispatch_request
    return self.view_functions[rule.endpoint](**req.view_args)
  File "E:\GraduationWork\ENV\lib\site-packages\flask_restful\__init__.py", line 458, in wrapper
    resp = resource(*args, **kwargs)
  File "E:\GraduationWork\ENV\lib\site-packages\flask\views.py", line 89, in view
    return self.dispatch_request(*args, **kwargs)
  File "E:\GraduationWork\ENV\lib\site-packages\flask_restful\__init__.py", line 573, in dispatch_request
    resp = meth(*args, **kwargs)
  File "E:\GraduationWork\DepartmentHandler\department-app\rest\api.py", line 50, in get
    data = crud.Departments.get_all()
  File "E:\GraduationWork\DepartmentHandler\department-app\service\crud.py", line 32, in get_all
    departments = Department.query.all()
  File "E:\GraduationWork\ENV\lib\site-packages\sqlalchemy\orm\query.py", line 3211, in all
    return list(self)
  File "E:\GraduationWork\ENV\lib\site-packages\sqlalchemy\orm\query.py", line 3367, in __iter__
    return self._execute_and_instances(context)
  File "E:\GraduationWork\ENV\lib\site-packages\sqlalchemy\orm\query.py", line 3392, in _execute_and_instances
    result = conn.execute(querycontext.statement, self._params)
  File "E:\GraduationWork\ENV\lib\site-packages\sqlalchemy\engine\base.py", line 982, in execute
    return meth(self, multiparams, params)
  File "E:\GraduationWork\ENV\lib\site-packages\sqlalchemy\sql\elements.py", line 287, in _execute_on_connection
    return connection._execute_clauseelement(self, multiparams, params)
  File "E:\GraduationWork\ENV\lib\site-packages\sqlalchemy\engine\base.py", line 1095, in _execute_clauseelement
    ret = self._execute_context(
  File "E:\GraduationWork\ENV\lib\site-packages\sqlalchemy\engine\base.py", line 1249, in _execute_context
    self._handle_dbapi_exception(
  File "E:\GraduationWork\ENV\lib\site-packages\sqlalchemy\engine\base.py", line 1476, in _handle_dbapi_exception
    util.raise_from_cause(sqlalchemy_exception, exc_info)
  File "E:\GraduationWork\ENV\lib\site-packages\sqlalchemy\util\compat.py", line 398, in raise_from_cause
    reraise(type(exception), exception, tb=exc_tb, cause=cause)
  File "E:\GraduationWork\ENV\lib\site-packages\sqlalchemy\util\compat.py", line 152, in reraise
    raise value.with_traceback(tb)
  File "E:\GraduationWork\ENV\lib\site-packages\sqlalchemy\engine\base.py", line 1245, in _execute_context
    self.dialect.do_execute(
  File "E:\GraduationWork\ENV\lib\site-packages\sqlalchemy\engine\default.py", line 581, in do_execute
    cursor.execute(statement, parameters)
  File "E:\GraduationWork\ENV\lib\site-packages\mysql\connector\cursor.py", line 551, in execute
    self._handle_result(self._connection.cmd_query(stmt))
  File "E:\GraduationWork\ENV\lib\site-packages\mysql\connector\connection.py", line 490, in cmd_query
    result = self._handle_result(self._send_cmd(ServerCmd.QUERY, query))
  File "E:\GraduationWork\ENV\lib\site-packages\mysql\connector\connection.py", line 395, in _handle_result
    raise errors.get_exception(packet)
sqlalchemy.exc.ProgrammingError: (mysql.connector.errors.ProgrammingError) 1146 (42S02): Table 'sql7323829.department' doesn't exist
[SQL: SELECT department.id AS department_id, department.name AS department_name 
FROM department]
(Background on this error at: http://sqlalche.me/e/f405)
2020-02-22 22:55:12,044 - rest.api - ERROR - Exception on /api/departments [GET]
Traceback (most recent call last):
  File "E:\GraduationWork\ENV\lib\site-packages\sqlalchemy\engine\base.py", line 1245, in _execute_context
    self.dialect.do_execute(
  File "E:\GraduationWork\ENV\lib\site-packages\sqlalchemy\engine\default.py", line 581, in do_execute
    cursor.execute(statement, parameters)
  File "E:\GraduationWork\ENV\lib\site-packages\mysql\connector\cursor.py", line 551, in execute
    self._handle_result(self._connection.cmd_query(stmt))
  File "E:\GraduationWork\ENV\lib\site-packages\mysql\connector\connection.py", line 490, in cmd_query
    result = self._handle_result(self._send_cmd(ServerCmd.QUERY, query))
  File "E:\GraduationWork\ENV\lib\site-packages\mysql\connector\connection.py", line 395, in _handle_result
    raise errors.get_exception(packet)
mysql.connector.errors.ProgrammingError: 1146 (42S02): Table 'sql7323829.department' doesn't exist

The above exception was the direct cause of the following exception:

Traceback (most recent call last):
  File "E:\GraduationWork\ENV\lib\site-packages\flask\app.py", line 1949, in full_dispatch_request
    rv = self.dispatch_request()
  File "E:\GraduationWork\ENV\lib\site-packages\flask\app.py", line 1935, in dispatch_request
    return self.view_functions[rule.endpoint](**req.view_args)
  File "E:\GraduationWork\ENV\lib\site-packages\flask_restful\__init__.py", line 458, in wrapper
    resp = resource(*args, **kwargs)
  File "E:\GraduationWork\ENV\lib\site-packages\flask\views.py", line 89, in view
    return self.dispatch_request(*args, **kwargs)
  File "E:\GraduationWork\ENV\lib\site-packages\flask_restful\__init__.py", line 573, in dispatch_request
    resp = meth(*args, **kwargs)
  File "E:\GraduationWork\DepartmentHandler\department-app\rest\api.py", line 50, in get
    data = crud.Departments.get_all()
  File "E:\GraduationWork\DepartmentHandler\department-app\service\crud.py", line 32, in get_all
    departments = Department.query.all()
  File "E:\GraduationWork\ENV\lib\site-packages\sqlalchemy\orm\query.py", line 3211, in all
    return list(self)
  File "E:\GraduationWork\ENV\lib\site-packages\sqlalchemy\orm\query.py", line 3367, in __iter__
    return self._execute_and_instances(context)
  File "E:\GraduationWork\ENV\lib\site-packages\sqlalchemy\orm\query.py", line 3392, in _execute_and_instances
    result = conn.execute(querycontext.statement, self._params)
  File "E:\GraduationWork\ENV\lib\site-packages\sqlalchemy\engine\base.py", line 982, in execute
    return meth(self, multiparams, params)
  File "E:\GraduationWork\ENV\lib\site-packages\sqlalchemy\sql\elements.py", line 287, in _execute_on_connection
    return connection._execute_clauseelement(self, multiparams, params)
  File "E:\GraduationWork\ENV\lib\site-packages\sqlalchemy\engine\base.py", line 1095, in _execute_clauseelement
    ret = self._execute_context(
  File "E:\GraduationWork\ENV\lib\site-packages\sqlalchemy\engine\base.py", line 1249, in _execute_context
    self._handle_dbapi_exception(
  File "E:\GraduationWork\ENV\lib\site-packages\sqlalchemy\engine\base.py", line 1476, in _handle_dbapi_exception
    util.raise_from_cause(sqlalchemy_exception, exc_info)
  File "E:\GraduationWork\ENV\lib\site-packages\sqlalchemy\util\compat.py", line 398, in raise_from_cause
    reraise(type(exception), exception, tb=exc_tb, cause=cause)
  File "E:\GraduationWork\ENV\lib\site-packages\sqlalchemy\util\compat.py", line 152, in reraise
    raise value.with_traceback(tb)
  File "E:\GraduationWork\ENV\lib\site-packages\sqlalchemy\engine\base.py", line 1245, in _execute_context
    self.dialect.do_execute(
  File "E:\GraduationWork\ENV\lib\site-packages\sqlalchemy\engine\default.py", line 581, in do_execute
    cursor.execute(statement, parameters)
  File "E:\GraduationWork\ENV\lib\site-packages\mysql\connector\cursor.py", line 551, in execute
    self._handle_result(self._connection.cmd_query(stmt))
  File "E:\GraduationWork\ENV\lib\site-packages\mysql\connector\connection.py", line 490, in cmd_query
    result = self._handle_result(self._send_cmd(ServerCmd.QUERY, query))
  File "E:\GraduationWork\ENV\lib\site-packages\mysql\connector\connection.py", line 395, in _handle_result
    raise errors.get_exception(packet)
sqlalchemy.exc.ProgrammingError: (mysql.connector.errors.ProgrammingError) 1146 (42S02): Table 'sql7323829.department' doesn't exist
[SQL: SELECT department.id AS department_id, department.name AS department_name 
FROM department]
(Background on this error at: http://sqlalche.me/e/f405)
2020-02-22 22:55:17,607 - rest.api - ERROR - Exception on /api/departments [GET]
Traceback (most recent call last):
  File "E:\GraduationWork\ENV\lib\site-packages\sqlalchemy\engine\base.py", line 1245, in _execute_context
    self.dialect.do_execute(
  File "E:\GraduationWork\ENV\lib\site-packages\sqlalchemy\engine\default.py", line 581, in do_execute
    cursor.execute(statement, parameters)
  File "E:\GraduationWork\ENV\lib\site-packages\mysql\connector\cursor.py", line 551, in execute
    self._handle_result(self._connection.cmd_query(stmt))
  File "E:\GraduationWork\ENV\lib\site-packages\mysql\connector\connection.py", line 490, in cmd_query
    result = self._handle_result(self._send_cmd(ServerCmd.QUERY, query))
  File "E:\GraduationWork\ENV\lib\site-packages\mysql\connector\connection.py", line 395, in _handle_result
    raise errors.get_exception(packet)
mysql.connector.errors.ProgrammingError: 1146 (42S02): Table 'sql7323829.department' doesn't exist

The above exception was the direct cause of the following exception:

Traceback (most recent call last):
  File "E:\GraduationWork\ENV\lib\site-packages\flask\app.py", line 1949, in full_dispatch_request
    rv = self.dispatch_request()
  File "E:\GraduationWork\ENV\lib\site-packages\flask\app.py", line 1935, in dispatch_request
    return self.view_functions[rule.endpoint](**req.view_args)
  File "E:\GraduationWork\ENV\lib\site-packages\flask_restful\__init__.py", line 458, in wrapper
    resp = resource(*args, **kwargs)
  File "E:\GraduationWork\ENV\lib\site-packages\flask\views.py", line 89, in view
    return self.dispatch_request(*args, **kwargs)
  File "E:\GraduationWork\ENV\lib\site-packages\flask_restful\__init__.py", line 573, in dispatch_request
    resp = meth(*args, **kwargs)
  File "E:\GraduationWork\DepartmentHandler\department-app\rest\api.py", line 50, in get
    data = crud.Departments.get_all()
  File "E:\GraduationWork\DepartmentHandler\department-app\service\crud.py", line 32, in get_all
    departments = Department.query.all()
  File "E:\GraduationWork\ENV\lib\site-packages\sqlalchemy\orm\query.py", line 3211, in all
    return list(self)
  File "E:\GraduationWork\ENV\lib\site-packages\sqlalchemy\orm\query.py", line 3367, in __iter__
    return self._execute_and_instances(context)
  File "E:\GraduationWork\ENV\lib\site-packages\sqlalchemy\orm\query.py", line 3392, in _execute_and_instances
    result = conn.execute(querycontext.statement, self._params)
  File "E:\GraduationWork\ENV\lib\site-packages\sqlalchemy\engine\base.py", line 982, in execute
    return meth(self, multiparams, params)
  File "E:\GraduationWork\ENV\lib\site-packages\sqlalchemy\sql\elements.py", line 287, in _execute_on_connection
    return connection._execute_clauseelement(self, multiparams, params)
  File "E:\GraduationWork\ENV\lib\site-packages\sqlalchemy\engine\base.py", line 1095, in _execute_clauseelement
    ret = self._execute_context(
  File "E:\GraduationWork\ENV\lib\site-packages\sqlalchemy\engine\base.py", line 1249, in _execute_context
    self._handle_dbapi_exception(
  File "E:\GraduationWork\ENV\lib\site-packages\sqlalchemy\engine\base.py", line 1476, in _handle_dbapi_exception
    util.raise_from_cause(sqlalchemy_exception, exc_info)
  File "E:\GraduationWork\ENV\lib\site-packages\sqlalchemy\util\compat.py", line 398, in raise_from_cause
    reraise(type(exception), exception, tb=exc_tb, cause=cause)
  File "E:\GraduationWork\ENV\lib\site-packages\sqlalchemy\util\compat.py", line 152, in reraise
    raise value.with_traceback(tb)
  File "E:\GraduationWork\ENV\lib\site-packages\sqlalchemy\engine\base.py", line 1245, in _execute_context
    self.dialect.do_execute(
  File "E:\GraduationWork\ENV\lib\site-packages\sqlalchemy\engine\default.py", line 581, in do_execute
    cursor.execute(statement, parameters)
  File "E:\GraduationWork\ENV\lib\site-packages\mysql\connector\cursor.py", line 551, in execute
    self._handle_result(self._connection.cmd_query(stmt))
  File "E:\GraduationWork\ENV\lib\site-packages\mysql\connector\connection.py", line 490, in cmd_query
    result = self._handle_result(self._send_cmd(ServerCmd.QUERY, query))
  File "E:\GraduationWork\ENV\lib\site-packages\mysql\connector\connection.py", line 395, in _handle_result
    raise errors.get_exception(packet)
sqlalchemy.exc.ProgrammingError: (mysql.connector.errors.ProgrammingError) 1146 (42S02): Table 'sql7323829.department' doesn't exist
[SQL: SELECT department.id AS department_id, department.name AS department_name 
FROM department]
(Background on this error at: http://sqlalche.me/e/f405)
2020-02-22 22:55:21,217 - rest.api - ERROR - Exception on /api/departments [GET]
Traceback (most recent call last):
  File "E:\GraduationWork\ENV\lib\site-packages\sqlalchemy\engine\base.py", line 1245, in _execute_context
    self.dialect.do_execute(
  File "E:\GraduationWork\ENV\lib\site-packages\sqlalchemy\engine\default.py", line 581, in do_execute
    cursor.execute(statement, parameters)
  File "E:\GraduationWork\ENV\lib\site-packages\mysql\connector\cursor.py", line 551, in execute
    self._handle_result(self._connection.cmd_query(stmt))
  File "E:\GraduationWork\ENV\lib\site-packages\mysql\connector\connection.py", line 490, in cmd_query
    result = self._handle_result(self._send_cmd(ServerCmd.QUERY, query))
  File "E:\GraduationWork\ENV\lib\site-packages\mysql\connector\connection.py", line 395, in _handle_result
    raise errors.get_exception(packet)
mysql.connector.errors.ProgrammingError: 1146 (42S02): Table 'sql7323829.department' doesn't exist

The above exception was the direct cause of the following exception:

Traceback (most recent call last):
  File "E:\GraduationWork\ENV\lib\site-packages\flask\app.py", line 1949, in full_dispatch_request
    rv = self.dispatch_request()
  File "E:\GraduationWork\ENV\lib\site-packages\flask\app.py", line 1935, in dispatch_request
    return self.view_functions[rule.endpoint](**req.view_args)
  File "E:\GraduationWork\ENV\lib\site-packages\flask_restful\__init__.py", line 458, in wrapper
    resp = resource(*args, **kwargs)
  File "E:\GraduationWork\ENV\lib\site-packages\flask\views.py", line 89, in view
    return self.dispatch_request(*args, **kwargs)
  File "E:\GraduationWork\ENV\lib\site-packages\flask_restful\__init__.py", line 573, in dispatch_request
    resp = meth(*args, **kwargs)
  File "E:\GraduationWork\DepartmentHandler\department-app\rest\api.py", line 50, in get
    data = crud.Departments.get_all()
  File "E:\GraduationWork\DepartmentHandler\department-app\service\crud.py", line 32, in get_all
    departments = Department.query.all()
  File "E:\GraduationWork\ENV\lib\site-packages\sqlalchemy\orm\query.py", line 3211, in all
    return list(self)
  File "E:\GraduationWork\ENV\lib\site-packages\sqlalchemy\orm\query.py", line 3367, in __iter__
    return self._execute_and_instances(context)
  File "E:\GraduationWork\ENV\lib\site-packages\sqlalchemy\orm\query.py", line 3392, in _execute_and_instances
    result = conn.execute(querycontext.statement, self._params)
  File "E:\GraduationWork\ENV\lib\site-packages\sqlalchemy\engine\base.py", line 982, in execute
    return meth(self, multiparams, params)
  File "E:\GraduationWork\ENV\lib\site-packages\sqlalchemy\sql\elements.py", line 287, in _execute_on_connection
    return connection._execute_clauseelement(self, multiparams, params)
  File "E:\GraduationWork\ENV\lib\site-packages\sqlalchemy\engine\base.py", line 1095, in _execute_clauseelement
    ret = self._execute_context(
  File "E:\GraduationWork\ENV\lib\site-packages\sqlalchemy\engine\base.py", line 1249, in _execute_context
    self._handle_dbapi_exception(
  File "E:\GraduationWork\ENV\lib\site-packages\sqlalchemy\engine\base.py", line 1476, in _handle_dbapi_exception
    util.raise_from_cause(sqlalchemy_exception, exc_info)
  File "E:\GraduationWork\ENV\lib\site-packages\sqlalchemy\util\compat.py", line 398, in raise_from_cause
    reraise(type(exception), exception, tb=exc_tb, cause=cause)
  File "E:\GraduationWork\ENV\lib\site-packages\sqlalchemy\util\compat.py", line 152, in reraise
    raise value.with_traceback(tb)
  File "E:\GraduationWork\ENV\lib\site-packages\sqlalchemy\engine\base.py", line 1245, in _execute_context
    self.dialect.do_execute(
  File "E:\GraduationWork\ENV\lib\site-packages\sqlalchemy\engine\default.py", line 581, in do_execute
    cursor.execute(statement, parameters)
  File "E:\GraduationWork\ENV\lib\site-packages\mysql\connector\cursor.py", line 551, in execute
    self._handle_result(self._connection.cmd_query(stmt))
  File "E:\GraduationWork\ENV\lib\site-packages\mysql\connector\connection.py", line 490, in cmd_query
    result = self._handle_result(self._send_cmd(ServerCmd.QUERY, query))
  File "E:\GraduationWork\ENV\lib\site-packages\mysql\connector\connection.py", line 395, in _handle_result
    raise errors.get_exception(packet)
sqlalchemy.exc.ProgrammingError: (mysql.connector.errors.ProgrammingError) 1146 (42S02): Table 'sql7323829.department' doesn't exist
[SQL: SELECT department.id AS department_id, department.name AS department_name 
FROM department]
(Background on this error at: http://sqlalche.me/e/f405)
2020-02-22 22:55:32,639 - rest.api - ERROR - Exception on /api/departments [GET]
Traceback (most recent call last):
  File "E:\GraduationWork\ENV\lib\site-packages\sqlalchemy\engine\base.py", line 1245, in _execute_context
    self.dialect.do_execute(
  File "E:\GraduationWork\ENV\lib\site-packages\sqlalchemy\engine\default.py", line 581, in do_execute
    cursor.execute(statement, parameters)
  File "E:\GraduationWork\ENV\lib\site-packages\mysql\connector\cursor.py", line 551, in execute
    self._handle_result(self._connection.cmd_query(stmt))
  File "E:\GraduationWork\ENV\lib\site-packages\mysql\connector\connection.py", line 490, in cmd_query
    result = self._handle_result(self._send_cmd(ServerCmd.QUERY, query))
  File "E:\GraduationWork\ENV\lib\site-packages\mysql\connector\connection.py", line 395, in _handle_result
    raise errors.get_exception(packet)
mysql.connector.errors.ProgrammingError: 1146 (42S02): Table 'sql7323829.department' doesn't exist

The above exception was the direct cause of the following exception:

Traceback (most recent call last):
  File "E:\GraduationWork\ENV\lib\site-packages\flask\app.py", line 1949, in full_dispatch_request
    rv = self.dispatch_request()
  File "E:\GraduationWork\ENV\lib\site-packages\flask\app.py", line 1935, in dispatch_request
    return self.view_functions[rule.endpoint](**req.view_args)
  File "E:\GraduationWork\ENV\lib\site-packages\flask_restful\__init__.py", line 458, in wrapper
    resp = resource(*args, **kwargs)
  File "E:\GraduationWork\ENV\lib\site-packages\flask\views.py", line 89, in view
    return self.dispatch_request(*args, **kwargs)
  File "E:\GraduationWork\ENV\lib\site-packages\flask_restful\__init__.py", line 573, in dispatch_request
    resp = meth(*args, **kwargs)
  File "E:\GraduationWork\DepartmentHandler\department-app\rest\api.py", line 50, in get
    data = crud.Departments.get_all()
  File "E:\GraduationWork\DepartmentHandler\department-app\service\crud.py", line 32, in get_all
    departments = Department.query.all()
  File "E:\GraduationWork\ENV\lib\site-packages\sqlalchemy\orm\query.py", line 3211, in all
    return list(self)
  File "E:\GraduationWork\ENV\lib\site-packages\sqlalchemy\orm\query.py", line 3367, in __iter__
    return self._execute_and_instances(context)
  File "E:\GraduationWork\ENV\lib\site-packages\sqlalchemy\orm\query.py", line 3392, in _execute_and_instances
    result = conn.execute(querycontext.statement, self._params)
  File "E:\GraduationWork\ENV\lib\site-packages\sqlalchemy\engine\base.py", line 982, in execute
    return meth(self, multiparams, params)
  File "E:\GraduationWork\ENV\lib\site-packages\sqlalchemy\sql\elements.py", line 287, in _execute_on_connection
    return connection._execute_clauseelement(self, multiparams, params)
  File "E:\GraduationWork\ENV\lib\site-packages\sqlalchemy\engine\base.py", line 1095, in _execute_clauseelement
    ret = self._execute_context(
  File "E:\GraduationWork\ENV\lib\site-packages\sqlalchemy\engine\base.py", line 1249, in _execute_context
    self._handle_dbapi_exception(
  File "E:\GraduationWork\ENV\lib\site-packages\sqlalchemy\engine\base.py", line 1476, in _handle_dbapi_exception
    util.raise_from_cause(sqlalchemy_exception, exc_info)
  File "E:\GraduationWork\ENV\lib\site-packages\sqlalchemy\util\compat.py", line 398, in raise_from_cause
    reraise(type(exception), exception, tb=exc_tb, cause=cause)
  File "E:\GraduationWork\ENV\lib\site-packages\sqlalchemy\util\compat.py", line 152, in reraise
    raise value.with_traceback(tb)
  File "E:\GraduationWork\ENV\lib\site-packages\sqlalchemy\engine\base.py", line 1245, in _execute_context
    self.dialect.do_execute(
  File "E:\GraduationWork\ENV\lib\site-packages\sqlalchemy\engine\default.py", line 581, in do_execute
    cursor.execute(statement, parameters)
  File "E:\GraduationWork\ENV\lib\site-packages\mysql\connector\cursor.py", line 551, in execute
    self._handle_result(self._connection.cmd_query(stmt))
  File "E:\GraduationWork\ENV\lib\site-packages\mysql\connector\connection.py", line 490, in cmd_query
    result = self._handle_result(self._send_cmd(ServerCmd.QUERY, query))
  File "E:\GraduationWork\ENV\lib\site-packages\mysql\connector\connection.py", line 395, in _handle_result
    raise errors.get_exception(packet)
sqlalchemy.exc.ProgrammingError: (mysql.connector.errors.ProgrammingError) 1146 (42S02): Table 'sql7323829.department' doesn't exist
[SQL: SELECT department.id AS department_id, department.name AS department_name 
FROM department]
(Background on this error at: http://sqlalche.me/e/f405)
2020-02-22 22:55:57,499 - rest.api - ERROR - Exception on /api/departments [GET]
Traceback (most recent call last):
  File "E:\GraduationWork\ENV\lib\site-packages\sqlalchemy\engine\base.py", line 1245, in _execute_context
    self.dialect.do_execute(
  File "E:\GraduationWork\ENV\lib\site-packages\sqlalchemy\engine\default.py", line 581, in do_execute
    cursor.execute(statement, parameters)
  File "E:\GraduationWork\ENV\lib\site-packages\mysql\connector\cursor.py", line 551, in execute
    self._handle_result(self._connection.cmd_query(stmt))
  File "E:\GraduationWork\ENV\lib\site-packages\mysql\connector\connection.py", line 490, in cmd_query
    result = self._handle_result(self._send_cmd(ServerCmd.QUERY, query))
  File "E:\GraduationWork\ENV\lib\site-packages\mysql\connector\connection.py", line 395, in _handle_result
    raise errors.get_exception(packet)
mysql.connector.errors.ProgrammingError: 1146 (42S02): Table 'sql7323829.department' doesn't exist

The above exception was the direct cause of the following exception:

Traceback (most recent call last):
  File "E:\GraduationWork\ENV\lib\site-packages\flask\app.py", line 1949, in full_dispatch_request
    rv = self.dispatch_request()
  File "E:\GraduationWork\ENV\lib\site-packages\flask\app.py", line 1935, in dispatch_request
    return self.view_functions[rule.endpoint](**req.view_args)
  File "E:\GraduationWork\ENV\lib\site-packages\flask_restful\__init__.py", line 458, in wrapper
    resp = resource(*args, **kwargs)
  File "E:\GraduationWork\ENV\lib\site-packages\flask\views.py", line 89, in view
    return self.dispatch_request(*args, **kwargs)
  File "E:\GraduationWork\ENV\lib\site-packages\flask_restful\__init__.py", line 573, in dispatch_request
    resp = meth(*args, **kwargs)
  File "E:\GraduationWork\DepartmentHandler\department-app\rest\api.py", line 50, in get
    data = crud.Departments.get_all()
  File "E:\GraduationWork\DepartmentHandler\department-app\service\crud.py", line 32, in get_all
    departments = Department.query.all()
  File "E:\GraduationWork\ENV\lib\site-packages\sqlalchemy\orm\query.py", line 3211, in all
    return list(self)
  File "E:\GraduationWork\ENV\lib\site-packages\sqlalchemy\orm\query.py", line 3367, in __iter__
    return self._execute_and_instances(context)
  File "E:\GraduationWork\ENV\lib\site-packages\sqlalchemy\orm\query.py", line 3392, in _execute_and_instances
    result = conn.execute(querycontext.statement, self._params)
  File "E:\GraduationWork\ENV\lib\site-packages\sqlalchemy\engine\base.py", line 982, in execute
    return meth(self, multiparams, params)
  File "E:\GraduationWork\ENV\lib\site-packages\sqlalchemy\sql\elements.py", line 287, in _execute_on_connection
    return connection._execute_clauseelement(self, multiparams, params)
  File "E:\GraduationWork\ENV\lib\site-packages\sqlalchemy\engine\base.py", line 1095, in _execute_clauseelement
    ret = self._execute_context(
  File "E:\GraduationWork\ENV\lib\site-packages\sqlalchemy\engine\base.py", line 1249, in _execute_context
    self._handle_dbapi_exception(
  File "E:\GraduationWork\ENV\lib\site-packages\sqlalchemy\engine\base.py", line 1476, in _handle_dbapi_exception
    util.raise_from_cause(sqlalchemy_exception, exc_info)
  File "E:\GraduationWork\ENV\lib\site-packages\sqlalchemy\util\compat.py", line 398, in raise_from_cause
    reraise(type(exception), exception, tb=exc_tb, cause=cause)
  File "E:\GraduationWork\ENV\lib\site-packages\sqlalchemy\util\compat.py", line 152, in reraise
    raise value.with_traceback(tb)
  File "E:\GraduationWork\ENV\lib\site-packages\sqlalchemy\engine\base.py", line 1245, in _execute_context
    self.dialect.do_execute(
  File "E:\GraduationWork\ENV\lib\site-packages\sqlalchemy\engine\default.py", line 581, in do_execute
    cursor.execute(statement, parameters)
  File "E:\GraduationWork\ENV\lib\site-packages\mysql\connector\cursor.py", line 551, in execute
    self._handle_result(self._connection.cmd_query(stmt))
  File "E:\GraduationWork\ENV\lib\site-packages\mysql\connector\connection.py", line 490, in cmd_query
    result = self._handle_result(self._send_cmd(ServerCmd.QUERY, query))
  File "E:\GraduationWork\ENV\lib\site-packages\mysql\connector\connection.py", line 395, in _handle_result
    raise errors.get_exception(packet)
sqlalchemy.exc.ProgrammingError: (mysql.connector.errors.ProgrammingError) 1146 (42S02): Table 'sql7323829.department' doesn't exist
[SQL: SELECT department.id AS department_id, department.name AS department_name 
FROM department]
(Background on this error at: http://sqlalche.me/e/f405)
2020-02-22 22:56:01,153 - rest.api - ERROR - Exception on /api/departments [GET]
Traceback (most recent call last):
  File "E:\GraduationWork\ENV\lib\site-packages\sqlalchemy\engine\base.py", line 1245, in _execute_context
    self.dialect.do_execute(
  File "E:\GraduationWork\ENV\lib\site-packages\sqlalchemy\engine\default.py", line 581, in do_execute
    cursor.execute(statement, parameters)
  File "E:\GraduationWork\ENV\lib\site-packages\mysql\connector\cursor.py", line 551, in execute
    self._handle_result(self._connection.cmd_query(stmt))
  File "E:\GraduationWork\ENV\lib\site-packages\mysql\connector\connection.py", line 490, in cmd_query
    result = self._handle_result(self._send_cmd(ServerCmd.QUERY, query))
  File "E:\GraduationWork\ENV\lib\site-packages\mysql\connector\connection.py", line 395, in _handle_result
    raise errors.get_exception(packet)
mysql.connector.errors.ProgrammingError: 1146 (42S02): Table 'sql7323829.department' doesn't exist

The above exception was the direct cause of the following exception:

Traceback (most recent call last):
  File "E:\GraduationWork\ENV\lib\site-packages\flask\app.py", line 1949, in full_dispatch_request
    rv = self.dispatch_request()
  File "E:\GraduationWork\ENV\lib\site-packages\flask\app.py", line 1935, in dispatch_request
    return self.view_functions[rule.endpoint](**req.view_args)
  File "E:\GraduationWork\ENV\lib\site-packages\flask_restful\__init__.py", line 458, in wrapper
    resp = resource(*args, **kwargs)
  File "E:\GraduationWork\ENV\lib\site-packages\flask\views.py", line 89, in view
    return self.dispatch_request(*args, **kwargs)
  File "E:\GraduationWork\ENV\lib\site-packages\flask_restful\__init__.py", line 573, in dispatch_request
    resp = meth(*args, **kwargs)
  File "E:\GraduationWork\DepartmentHandler\department-app\rest\api.py", line 50, in get
    data = crud.Departments.get_all()
  File "E:\GraduationWork\DepartmentHandler\department-app\service\crud.py", line 32, in get_all
    departments = Department.query.all()
  File "E:\GraduationWork\ENV\lib\site-packages\sqlalchemy\orm\query.py", line 3211, in all
    return list(self)
  File "E:\GraduationWork\ENV\lib\site-packages\sqlalchemy\orm\query.py", line 3367, in __iter__
    return self._execute_and_instances(context)
  File "E:\GraduationWork\ENV\lib\site-packages\sqlalchemy\orm\query.py", line 3392, in _execute_and_instances
    result = conn.execute(querycontext.statement, self._params)
  File "E:\GraduationWork\ENV\lib\site-packages\sqlalchemy\engine\base.py", line 982, in execute
    return meth(self, multiparams, params)
  File "E:\GraduationWork\ENV\lib\site-packages\sqlalchemy\sql\elements.py", line 287, in _execute_on_connection
    return connection._execute_clauseelement(self, multiparams, params)
  File "E:\GraduationWork\ENV\lib\site-packages\sqlalchemy\engine\base.py", line 1095, in _execute_clauseelement
    ret = self._execute_context(
  File "E:\GraduationWork\ENV\lib\site-packages\sqlalchemy\engine\base.py", line 1249, in _execute_context
    self._handle_dbapi_exception(
  File "E:\GraduationWork\ENV\lib\site-packages\sqlalchemy\engine\base.py", line 1476, in _handle_dbapi_exception
    util.raise_from_cause(sqlalchemy_exception, exc_info)
  File "E:\GraduationWork\ENV\lib\site-packages\sqlalchemy\util\compat.py", line 398, in raise_from_cause
    reraise(type(exception), exception, tb=exc_tb, cause=cause)
  File "E:\GraduationWork\ENV\lib\site-packages\sqlalchemy\util\compat.py", line 152, in reraise
    raise value.with_traceback(tb)
  File "E:\GraduationWork\ENV\lib\site-packages\sqlalchemy\engine\base.py", line 1245, in _execute_context
    self.dialect.do_execute(
  File "E:\GraduationWork\ENV\lib\site-packages\sqlalchemy\engine\default.py", line 581, in do_execute
    cursor.execute(statement, parameters)
  File "E:\GraduationWork\ENV\lib\site-packages\mysql\connector\cursor.py", line 551, in execute
    self._handle_result(self._connection.cmd_query(stmt))
  File "E:\GraduationWork\ENV\lib\site-packages\mysql\connector\connection.py", line 490, in cmd_query
    result = self._handle_result(self._send_cmd(ServerCmd.QUERY, query))
  File "E:\GraduationWork\ENV\lib\site-packages\mysql\connector\connection.py", line 395, in _handle_result
    raise errors.get_exception(packet)
sqlalchemy.exc.ProgrammingError: (mysql.connector.errors.ProgrammingError) 1146 (42S02): Table 'sql7323829.department' doesn't exist
[SQL: SELECT department.id AS department_id, department.name AS department_name 
FROM department]
(Background on this error at: http://sqlalche.me/e/f405)
2020-02-22 23:05:52,245 - rest.api - ERROR - Exception on /api/departments [GET]
Traceback (most recent call last):
  File "E:\GraduationWork\ENV\lib\site-packages\sqlalchemy\engine\base.py", line 1245, in _execute_context
    self.dialect.do_execute(
  File "E:\GraduationWork\ENV\lib\site-packages\sqlalchemy\engine\default.py", line 581, in do_execute
    cursor.execute(statement, parameters)
  File "E:\GraduationWork\ENV\lib\site-packages\mysql\connector\cursor.py", line 551, in execute
    self._handle_result(self._connection.cmd_query(stmt))
  File "E:\GraduationWork\ENV\lib\site-packages\mysql\connector\connection.py", line 490, in cmd_query
    result = self._handle_result(self._send_cmd(ServerCmd.QUERY, query))
  File "E:\GraduationWork\ENV\lib\site-packages\mysql\connector\connection.py", line 395, in _handle_result
    raise errors.get_exception(packet)
mysql.connector.errors.ProgrammingError: 1146 (42S02): Table 'sql7323829.department' doesn't exist

The above exception was the direct cause of the following exception:

Traceback (most recent call last):
  File "E:\GraduationWork\ENV\lib\site-packages\flask\app.py", line 1949, in full_dispatch_request
    rv = self.dispatch_request()
  File "E:\GraduationWork\ENV\lib\site-packages\flask\app.py", line 1935, in dispatch_request
    return self.view_functions[rule.endpoint](**req.view_args)
  File "E:\GraduationWork\ENV\lib\site-packages\flask_restful\__init__.py", line 458, in wrapper
    resp = resource(*args, **kwargs)
  File "E:\GraduationWork\ENV\lib\site-packages\flask\views.py", line 89, in view
    return self.dispatch_request(*args, **kwargs)
  File "E:\GraduationWork\ENV\lib\site-packages\flask_restful\__init__.py", line 573, in dispatch_request
    resp = meth(*args, **kwargs)
  File "E:\GraduationWork\DepartmentHandler\department-app\rest\api.py", line 50, in get
    data = crud.Departments.get_all()
  File "E:\GraduationWork\DepartmentHandler\department-app\service\crud.py", line 32, in get_all
    departments = Department.query.all()
  File "E:\GraduationWork\ENV\lib\site-packages\sqlalchemy\orm\query.py", line 3211, in all
    return list(self)
  File "E:\GraduationWork\ENV\lib\site-packages\sqlalchemy\orm\query.py", line 3367, in __iter__
    return self._execute_and_instances(context)
  File "E:\GraduationWork\ENV\lib\site-packages\sqlalchemy\orm\query.py", line 3392, in _execute_and_instances
    result = conn.execute(querycontext.statement, self._params)
  File "E:\GraduationWork\ENV\lib\site-packages\sqlalchemy\engine\base.py", line 982, in execute
    return meth(self, multiparams, params)
  File "E:\GraduationWork\ENV\lib\site-packages\sqlalchemy\sql\elements.py", line 287, in _execute_on_connection
    return connection._execute_clauseelement(self, multiparams, params)
  File "E:\GraduationWork\ENV\lib\site-packages\sqlalchemy\engine\base.py", line 1095, in _execute_clauseelement
    ret = self._execute_context(
  File "E:\GraduationWork\ENV\lib\site-packages\sqlalchemy\engine\base.py", line 1249, in _execute_context
    self._handle_dbapi_exception(
  File "E:\GraduationWork\ENV\lib\site-packages\sqlalchemy\engine\base.py", line 1476, in _handle_dbapi_exception
    util.raise_from_cause(sqlalchemy_exception, exc_info)
  File "E:\GraduationWork\ENV\lib\site-packages\sqlalchemy\util\compat.py", line 398, in raise_from_cause
    reraise(type(exception), exception, tb=exc_tb, cause=cause)
  File "E:\GraduationWork\ENV\lib\site-packages\sqlalchemy\util\compat.py", line 152, in reraise
    raise value.with_traceback(tb)
  File "E:\GraduationWork\ENV\lib\site-packages\sqlalchemy\engine\base.py", line 1245, in _execute_context
    self.dialect.do_execute(
  File "E:\GraduationWork\ENV\lib\site-packages\sqlalchemy\engine\default.py", line 581, in do_execute
    cursor.execute(statement, parameters)
  File "E:\GraduationWork\ENV\lib\site-packages\mysql\connector\cursor.py", line 551, in execute
    self._handle_result(self._connection.cmd_query(stmt))
  File "E:\GraduationWork\ENV\lib\site-packages\mysql\connector\connection.py", line 490, in cmd_query
    result = self._handle_result(self._send_cmd(ServerCmd.QUERY, query))
  File "E:\GraduationWork\ENV\lib\site-packages\mysql\connector\connection.py", line 395, in _handle_result
    raise errors.get_exception(packet)
sqlalchemy.exc.ProgrammingError: (mysql.connector.errors.ProgrammingError) 1146 (42S02): Table 'sql7323829.department' doesn't exist
[SQL: SELECT department.id AS department_id, department.name AS department_name 
FROM department]
(Background on this error at: http://sqlalche.me/e/f405)
2020-02-22 23:16:35,118 - rest.api - ERROR - Exception on /api/departments [GET]
Traceback (most recent call last):
  File "E:\GraduationWork\ENV\lib\site-packages\sqlalchemy\engine\base.py", line 1245, in _execute_context
    self.dialect.do_execute(
  File "E:\GraduationWork\ENV\lib\site-packages\sqlalchemy\engine\default.py", line 581, in do_execute
    cursor.execute(statement, parameters)
  File "E:\GraduationWork\ENV\lib\site-packages\mysql\connector\cursor.py", line 551, in execute
    self._handle_result(self._connection.cmd_query(stmt))
  File "E:\GraduationWork\ENV\lib\site-packages\mysql\connector\connection.py", line 490, in cmd_query
    result = self._handle_result(self._send_cmd(ServerCmd.QUERY, query))
  File "E:\GraduationWork\ENV\lib\site-packages\mysql\connector\connection.py", line 395, in _handle_result
    raise errors.get_exception(packet)
mysql.connector.errors.ProgrammingError: 1146 (42S02): Table 'sql7323829.department' doesn't exist

The above exception was the direct cause of the following exception:

Traceback (most recent call last):
  File "E:\GraduationWork\ENV\lib\site-packages\flask\app.py", line 1949, in full_dispatch_request
    rv = self.dispatch_request()
  File "E:\GraduationWork\ENV\lib\site-packages\flask\app.py", line 1935, in dispatch_request
    return self.view_functions[rule.endpoint](**req.view_args)
  File "E:\GraduationWork\ENV\lib\site-packages\flask_restful\__init__.py", line 458, in wrapper
    resp = resource(*args, **kwargs)
  File "E:\GraduationWork\ENV\lib\site-packages\flask\views.py", line 89, in view
    return self.dispatch_request(*args, **kwargs)
  File "E:\GraduationWork\ENV\lib\site-packages\flask_restful\__init__.py", line 573, in dispatch_request
    resp = meth(*args, **kwargs)
  File "E:\GraduationWork\DepartmentHandler\department-app\rest\api.py", line 50, in get
    data = crud.Departments.get_all()
  File "E:\GraduationWork\DepartmentHandler\department-app\service\crud.py", line 32, in get_all
    departments = Department.query.all()
  File "E:\GraduationWork\ENV\lib\site-packages\sqlalchemy\orm\query.py", line 3211, in all
    return list(self)
  File "E:\GraduationWork\ENV\lib\site-packages\sqlalchemy\orm\query.py", line 3367, in __iter__
    return self._execute_and_instances(context)
  File "E:\GraduationWork\ENV\lib\site-packages\sqlalchemy\orm\query.py", line 3392, in _execute_and_instances
    result = conn.execute(querycontext.statement, self._params)
  File "E:\GraduationWork\ENV\lib\site-packages\sqlalchemy\engine\base.py", line 982, in execute
    return meth(self, multiparams, params)
  File "E:\GraduationWork\ENV\lib\site-packages\sqlalchemy\sql\elements.py", line 287, in _execute_on_connection
    return connection._execute_clauseelement(self, multiparams, params)
  File "E:\GraduationWork\ENV\lib\site-packages\sqlalchemy\engine\base.py", line 1095, in _execute_clauseelement
    ret = self._execute_context(
  File "E:\GraduationWork\ENV\lib\site-packages\sqlalchemy\engine\base.py", line 1249, in _execute_context
    self._handle_dbapi_exception(
  File "E:\GraduationWork\ENV\lib\site-packages\sqlalchemy\engine\base.py", line 1476, in _handle_dbapi_exception
    util.raise_from_cause(sqlalchemy_exception, exc_info)
  File "E:\GraduationWork\ENV\lib\site-packages\sqlalchemy\util\compat.py", line 398, in raise_from_cause
    reraise(type(exception), exception, tb=exc_tb, cause=cause)
  File "E:\GraduationWork\ENV\lib\site-packages\sqlalchemy\util\compat.py", line 152, in reraise
    raise value.with_traceback(tb)
  File "E:\GraduationWork\ENV\lib\site-packages\sqlalchemy\engine\base.py", line 1245, in _execute_context
    self.dialect.do_execute(
  File "E:\GraduationWork\ENV\lib\site-packages\sqlalchemy\engine\default.py", line 581, in do_execute
    cursor.execute(statement, parameters)
  File "E:\GraduationWork\ENV\lib\site-packages\mysql\connector\cursor.py", line 551, in execute
    self._handle_result(self._connection.cmd_query(stmt))
  File "E:\GraduationWork\ENV\lib\site-packages\mysql\connector\connection.py", line 490, in cmd_query
    result = self._handle_result(self._send_cmd(ServerCmd.QUERY, query))
  File "E:\GraduationWork\ENV\lib\site-packages\mysql\connector\connection.py", line 395, in _handle_result
    raise errors.get_exception(packet)
sqlalchemy.exc.ProgrammingError: (mysql.connector.errors.ProgrammingError) 1146 (42S02): Table 'sql7323829.department' doesn't exist
[SQL: SELECT department.id AS department_id, department.name AS department_name 
FROM department]
(Background on this error at: http://sqlalche.me/e/f405)
2020-02-22 23:16:41,200 - service.crud - DEBUG - List of employees was returned
2020-02-22 23:16:41,664 - rest.api - ERROR - Exception on /api/employees [GET]
Traceback (most recent call last):
  File "E:\GraduationWork\ENV\lib\site-packages\sqlalchemy\engine\base.py", line 1245, in _execute_context
    self.dialect.do_execute(
  File "E:\GraduationWork\ENV\lib\site-packages\sqlalchemy\engine\default.py", line 581, in do_execute
    cursor.execute(statement, parameters)
  File "E:\GraduationWork\ENV\lib\site-packages\mysql\connector\cursor.py", line 551, in execute
    self._handle_result(self._connection.cmd_query(stmt))
  File "E:\GraduationWork\ENV\lib\site-packages\mysql\connector\connection.py", line 490, in cmd_query
    result = self._handle_result(self._send_cmd(ServerCmd.QUERY, query))
  File "E:\GraduationWork\ENV\lib\site-packages\mysql\connector\connection.py", line 395, in _handle_result
    raise errors.get_exception(packet)
mysql.connector.errors.ProgrammingError: 1146 (42S02): Table 'sql7323829.employee' doesn't exist

The above exception was the direct cause of the following exception:

Traceback (most recent call last):
  File "E:\GraduationWork\ENV\lib\site-packages\flask\app.py", line 1949, in full_dispatch_request
    rv = self.dispatch_request()
  File "E:\GraduationWork\ENV\lib\site-packages\flask\app.py", line 1935, in dispatch_request
    return self.view_functions[rule.endpoint](**req.view_args)
  File "E:\GraduationWork\ENV\lib\site-packages\flask_restful\__init__.py", line 458, in wrapper
    resp = resource(*args, **kwargs)
  File "E:\GraduationWork\ENV\lib\site-packages\flask\views.py", line 89, in view
    return self.dispatch_request(*args, **kwargs)
  File "E:\GraduationWork\ENV\lib\site-packages\flask_restful\__init__.py", line 573, in dispatch_request
    resp = meth(*args, **kwargs)
  File "E:\GraduationWork\DepartmentHandler\department-app\rest\api.py", line 180, in get
    employees = crud.Employees.get_all()
  File "E:\GraduationWork\DepartmentHandler\department-app\service\crud.py", line 128, in get_all
    return Employee.query.all()
  File "E:\GraduationWork\ENV\lib\site-packages\sqlalchemy\orm\query.py", line 3211, in all
    return list(self)
  File "E:\GraduationWork\ENV\lib\site-packages\sqlalchemy\orm\query.py", line 3367, in __iter__
    return self._execute_and_instances(context)
  File "E:\GraduationWork\ENV\lib\site-packages\sqlalchemy\orm\query.py", line 3392, in _execute_and_instances
    result = conn.execute(querycontext.statement, self._params)
  File "E:\GraduationWork\ENV\lib\site-packages\sqlalchemy\engine\base.py", line 982, in execute
    return meth(self, multiparams, params)
  File "E:\GraduationWork\ENV\lib\site-packages\sqlalchemy\sql\elements.py", line 287, in _execute_on_connection
    return connection._execute_clauseelement(self, multiparams, params)
  File "E:\GraduationWork\ENV\lib\site-packages\sqlalchemy\engine\base.py", line 1095, in _execute_clauseelement
    ret = self._execute_context(
  File "E:\GraduationWork\ENV\lib\site-packages\sqlalchemy\engine\base.py", line 1249, in _execute_context
    self._handle_dbapi_exception(
  File "E:\GraduationWork\ENV\lib\site-packages\sqlalchemy\engine\base.py", line 1476, in _handle_dbapi_exception
    util.raise_from_cause(sqlalchemy_exception, exc_info)
  File "E:\GraduationWork\ENV\lib\site-packages\sqlalchemy\util\compat.py", line 398, in raise_from_cause
    reraise(type(exception), exception, tb=exc_tb, cause=cause)
  File "E:\GraduationWork\ENV\lib\site-packages\sqlalchemy\util\compat.py", line 152, in reraise
    raise value.with_traceback(tb)
  File "E:\GraduationWork\ENV\lib\site-packages\sqlalchemy\engine\base.py", line 1245, in _execute_context
    self.dialect.do_execute(
  File "E:\GraduationWork\ENV\lib\site-packages\sqlalchemy\engine\default.py", line 581, in do_execute
    cursor.execute(statement, parameters)
  File "E:\GraduationWork\ENV\lib\site-packages\mysql\connector\cursor.py", line 551, in execute
    self._handle_result(self._connection.cmd_query(stmt))
  File "E:\GraduationWork\ENV\lib\site-packages\mysql\connector\connection.py", line 490, in cmd_query
    result = self._handle_result(self._send_cmd(ServerCmd.QUERY, query))
  File "E:\GraduationWork\ENV\lib\site-packages\mysql\connector\connection.py", line 395, in _handle_result
    raise errors.get_exception(packet)
sqlalchemy.exc.ProgrammingError: (mysql.connector.errors.ProgrammingError) 1146 (42S02): Table 'sql7323829.employee' doesn't exist
[SQL: SELECT employee.id AS employee_id, employee.name AS employee_name, employee.department_id AS employee_department_id, employee.date_of_birthday AS employee_date_of_birthday, employee.salary AS employee_salary 
FROM employee]
(Background on this error at: http://sqlalche.me/e/f405)
2020-02-22 23:18:50,604 - service.crud - DEBUG - List of employees was returned
2020-02-22 23:18:50,824 - rest.api - ERROR - Exception on /api/employees [GET]
Traceback (most recent call last):
  File "E:\GraduationWork\ENV\lib\site-packages\sqlalchemy\engine\base.py", line 1245, in _execute_context
    self.dialect.do_execute(
  File "E:\GraduationWork\ENV\lib\site-packages\sqlalchemy\engine\default.py", line 581, in do_execute
    cursor.execute(statement, parameters)
  File "E:\GraduationWork\ENV\lib\site-packages\mysql\connector\cursor.py", line 551, in execute
    self._handle_result(self._connection.cmd_query(stmt))
  File "E:\GraduationWork\ENV\lib\site-packages\mysql\connector\connection.py", line 490, in cmd_query
    result = self._handle_result(self._send_cmd(ServerCmd.QUERY, query))
  File "E:\GraduationWork\ENV\lib\site-packages\mysql\connector\connection.py", line 395, in _handle_result
    raise errors.get_exception(packet)
mysql.connector.errors.ProgrammingError: 1146 (42S02): Table 'sql7323829.employee' doesn't exist

The above exception was the direct cause of the following exception:

Traceback (most recent call last):
  File "E:\GraduationWork\ENV\lib\site-packages\flask\app.py", line 1949, in full_dispatch_request
    rv = self.dispatch_request()
  File "E:\GraduationWork\ENV\lib\site-packages\flask\app.py", line 1935, in dispatch_request
    return self.view_functions[rule.endpoint](**req.view_args)
  File "E:\GraduationWork\ENV\lib\site-packages\flask_restful\__init__.py", line 458, in wrapper
    resp = resource(*args, **kwargs)
  File "E:\GraduationWork\ENV\lib\site-packages\flask\views.py", line 89, in view
    return self.dispatch_request(*args, **kwargs)
  File "E:\GraduationWork\ENV\lib\site-packages\flask_restful\__init__.py", line 573, in dispatch_request
    resp = meth(*args, **kwargs)
  File "E:\GraduationWork\DepartmentHandler\department-app\rest\api.py", line 180, in get
    employees = crud.Employees.get_all()
  File "E:\GraduationWork\DepartmentHandler\department-app\service\crud.py", line 128, in get_all
    return Employee.query.all()
  File "E:\GraduationWork\ENV\lib\site-packages\sqlalchemy\orm\query.py", line 3211, in all
    return list(self)
  File "E:\GraduationWork\ENV\lib\site-packages\sqlalchemy\orm\query.py", line 3367, in __iter__
    return self._execute_and_instances(context)
  File "E:\GraduationWork\ENV\lib\site-packages\sqlalchemy\orm\query.py", line 3392, in _execute_and_instances
    result = conn.execute(querycontext.statement, self._params)
  File "E:\GraduationWork\ENV\lib\site-packages\sqlalchemy\engine\base.py", line 982, in execute
    return meth(self, multiparams, params)
  File "E:\GraduationWork\ENV\lib\site-packages\sqlalchemy\sql\elements.py", line 287, in _execute_on_connection
    return connection._execute_clauseelement(self, multiparams, params)
  File "E:\GraduationWork\ENV\lib\site-packages\sqlalchemy\engine\base.py", line 1095, in _execute_clauseelement
    ret = self._execute_context(
  File "E:\GraduationWork\ENV\lib\site-packages\sqlalchemy\engine\base.py", line 1249, in _execute_context
    self._handle_dbapi_exception(
  File "E:\GraduationWork\ENV\lib\site-packages\sqlalchemy\engine\base.py", line 1476, in _handle_dbapi_exception
    util.raise_from_cause(sqlalchemy_exception, exc_info)
  File "E:\GraduationWork\ENV\lib\site-packages\sqlalchemy\util\compat.py", line 398, in raise_from_cause
    reraise(type(exception), exception, tb=exc_tb, cause=cause)
  File "E:\GraduationWork\ENV\lib\site-packages\sqlalchemy\util\compat.py", line 152, in reraise
    raise value.with_traceback(tb)
  File "E:\GraduationWork\ENV\lib\site-packages\sqlalchemy\engine\base.py", line 1245, in _execute_context
    self.dialect.do_execute(
  File "E:\GraduationWork\ENV\lib\site-packages\sqlalchemy\engine\default.py", line 581, in do_execute
    cursor.execute(statement, parameters)
  File "E:\GraduationWork\ENV\lib\site-packages\mysql\connector\cursor.py", line 551, in execute
    self._handle_result(self._connection.cmd_query(stmt))
  File "E:\GraduationWork\ENV\lib\site-packages\mysql\connector\connection.py", line 490, in cmd_query
    result = self._handle_result(self._send_cmd(ServerCmd.QUERY, query))
  File "E:\GraduationWork\ENV\lib\site-packages\mysql\connector\connection.py", line 395, in _handle_result
    raise errors.get_exception(packet)
sqlalchemy.exc.ProgrammingError: (mysql.connector.errors.ProgrammingError) 1146 (42S02): Table 'sql7323829.employee' doesn't exist
[SQL: SELECT employee.id AS employee_id, employee.name AS employee_name, employee.department_id AS employee_department_id, employee.date_of_birthday AS employee_date_of_birthday, employee.salary AS employee_salary 
FROM employee]
(Background on this error at: http://sqlalche.me/e/f405)
2020-02-22 23:18:54,956 - rest.api - ERROR - Exception on /api/departments [GET]
Traceback (most recent call last):
  File "E:\GraduationWork\ENV\lib\site-packages\sqlalchemy\engine\base.py", line 1245, in _execute_context
    self.dialect.do_execute(
  File "E:\GraduationWork\ENV\lib\site-packages\sqlalchemy\engine\default.py", line 581, in do_execute
    cursor.execute(statement, parameters)
  File "E:\GraduationWork\ENV\lib\site-packages\mysql\connector\cursor.py", line 551, in execute
    self._handle_result(self._connection.cmd_query(stmt))
  File "E:\GraduationWork\ENV\lib\site-packages\mysql\connector\connection.py", line 490, in cmd_query
    result = self._handle_result(self._send_cmd(ServerCmd.QUERY, query))
  File "E:\GraduationWork\ENV\lib\site-packages\mysql\connector\connection.py", line 395, in _handle_result
    raise errors.get_exception(packet)
mysql.connector.errors.ProgrammingError: 1146 (42S02): Table 'sql7323829.department' doesn't exist

The above exception was the direct cause of the following exception:

Traceback (most recent call last):
  File "E:\GraduationWork\ENV\lib\site-packages\flask\app.py", line 1949, in full_dispatch_request
    rv = self.dispatch_request()
  File "E:\GraduationWork\ENV\lib\site-packages\flask\app.py", line 1935, in dispatch_request
    return self.view_functions[rule.endpoint](**req.view_args)
  File "E:\GraduationWork\ENV\lib\site-packages\flask_restful\__init__.py", line 458, in wrapper
    resp = resource(*args, **kwargs)
  File "E:\GraduationWork\ENV\lib\site-packages\flask\views.py", line 89, in view
    return self.dispatch_request(*args, **kwargs)
  File "E:\GraduationWork\ENV\lib\site-packages\flask_restful\__init__.py", line 573, in dispatch_request
    resp = meth(*args, **kwargs)
  File "E:\GraduationWork\DepartmentHandler\department-app\rest\api.py", line 50, in get
    data = crud.Departments.get_all()
  File "E:\GraduationWork\DepartmentHandler\department-app\service\crud.py", line 32, in get_all
    departments = Department.query.all()
  File "E:\GraduationWork\ENV\lib\site-packages\sqlalchemy\orm\query.py", line 3211, in all
    return list(self)
  File "E:\GraduationWork\ENV\lib\site-packages\sqlalchemy\orm\query.py", line 3367, in __iter__
    return self._execute_and_instances(context)
  File "E:\GraduationWork\ENV\lib\site-packages\sqlalchemy\orm\query.py", line 3392, in _execute_and_instances
    result = conn.execute(querycontext.statement, self._params)
  File "E:\GraduationWork\ENV\lib\site-packages\sqlalchemy\engine\base.py", line 982, in execute
    return meth(self, multiparams, params)
  File "E:\GraduationWork\ENV\lib\site-packages\sqlalchemy\sql\elements.py", line 287, in _execute_on_connection
    return connection._execute_clauseelement(self, multiparams, params)
  File "E:\GraduationWork\ENV\lib\site-packages\sqlalchemy\engine\base.py", line 1095, in _execute_clauseelement
    ret = self._execute_context(
  File "E:\GraduationWork\ENV\lib\site-packages\sqlalchemy\engine\base.py", line 1249, in _execute_context
    self._handle_dbapi_exception(
  File "E:\GraduationWork\ENV\lib\site-packages\sqlalchemy\engine\base.py", line 1476, in _handle_dbapi_exception
    util.raise_from_cause(sqlalchemy_exception, exc_info)
  File "E:\GraduationWork\ENV\lib\site-packages\sqlalchemy\util\compat.py", line 398, in raise_from_cause
    reraise(type(exception), exception, tb=exc_tb, cause=cause)
  File "E:\GraduationWork\ENV\lib\site-packages\sqlalchemy\util\compat.py", line 152, in reraise
    raise value.with_traceback(tb)
  File "E:\GraduationWork\ENV\lib\site-packages\sqlalchemy\engine\base.py", line 1245, in _execute_context
    self.dialect.do_execute(
  File "E:\GraduationWork\ENV\lib\site-packages\sqlalchemy\engine\default.py", line 581, in do_execute
    cursor.execute(statement, parameters)
  File "E:\GraduationWork\ENV\lib\site-packages\mysql\connector\cursor.py", line 551, in execute
    self._handle_result(self._connection.cmd_query(stmt))
  File "E:\GraduationWork\ENV\lib\site-packages\mysql\connector\connection.py", line 490, in cmd_query
    result = self._handle_result(self._send_cmd(ServerCmd.QUERY, query))
  File "E:\GraduationWork\ENV\lib\site-packages\mysql\connector\connection.py", line 395, in _handle_result
    raise errors.get_exception(packet)
sqlalchemy.exc.ProgrammingError: (mysql.connector.errors.ProgrammingError) 1146 (42S02): Table 'sql7323829.department' doesn't exist
[SQL: SELECT department.id AS department_id, department.name AS department_name 
FROM department]
(Background on this error at: http://sqlalche.me/e/f405)
2020-02-22 23:18:56,505 - service.crud - DEBUG - List of employees was returned
2020-02-22 23:18:56,821 - rest.api - ERROR - Exception on /api/employees [GET]
Traceback (most recent call last):
  File "E:\GraduationWork\ENV\lib\site-packages\sqlalchemy\engine\base.py", line 1245, in _execute_context
    self.dialect.do_execute(
  File "E:\GraduationWork\ENV\lib\site-packages\sqlalchemy\engine\default.py", line 581, in do_execute
    cursor.execute(statement, parameters)
  File "E:\GraduationWork\ENV\lib\site-packages\mysql\connector\cursor.py", line 551, in execute
    self._handle_result(self._connection.cmd_query(stmt))
  File "E:\GraduationWork\ENV\lib\site-packages\mysql\connector\connection.py", line 490, in cmd_query
    result = self._handle_result(self._send_cmd(ServerCmd.QUERY, query))
  File "E:\GraduationWork\ENV\lib\site-packages\mysql\connector\connection.py", line 395, in _handle_result
    raise errors.get_exception(packet)
mysql.connector.errors.ProgrammingError: 1146 (42S02): Table 'sql7323829.employee' doesn't exist

The above exception was the direct cause of the following exception:

Traceback (most recent call last):
  File "E:\GraduationWork\ENV\lib\site-packages\flask\app.py", line 1949, in full_dispatch_request
    rv = self.dispatch_request()
  File "E:\GraduationWork\ENV\lib\site-packages\flask\app.py", line 1935, in dispatch_request
    return self.view_functions[rule.endpoint](**req.view_args)
  File "E:\GraduationWork\ENV\lib\site-packages\flask_restful\__init__.py", line 458, in wrapper
    resp = resource(*args, **kwargs)
  File "E:\GraduationWork\ENV\lib\site-packages\flask\views.py", line 89, in view
    return self.dispatch_request(*args, **kwargs)
  File "E:\GraduationWork\ENV\lib\site-packages\flask_restful\__init__.py", line 573, in dispatch_request
    resp = meth(*args, **kwargs)
  File "E:\GraduationWork\DepartmentHandler\department-app\rest\api.py", line 180, in get
    employees = crud.Employees.get_all()
  File "E:\GraduationWork\DepartmentHandler\department-app\service\crud.py", line 128, in get_all
    return Employee.query.all()
  File "E:\GraduationWork\ENV\lib\site-packages\sqlalchemy\orm\query.py", line 3211, in all
    return list(self)
  File "E:\GraduationWork\ENV\lib\site-packages\sqlalchemy\orm\query.py", line 3367, in __iter__
    return self._execute_and_instances(context)
  File "E:\GraduationWork\ENV\lib\site-packages\sqlalchemy\orm\query.py", line 3392, in _execute_and_instances
    result = conn.execute(querycontext.statement, self._params)
  File "E:\GraduationWork\ENV\lib\site-packages\sqlalchemy\engine\base.py", line 982, in execute
    return meth(self, multiparams, params)
  File "E:\GraduationWork\ENV\lib\site-packages\sqlalchemy\sql\elements.py", line 287, in _execute_on_connection
    return connection._execute_clauseelement(self, multiparams, params)
  File "E:\GraduationWork\ENV\lib\site-packages\sqlalchemy\engine\base.py", line 1095, in _execute_clauseelement
    ret = self._execute_context(
  File "E:\GraduationWork\ENV\lib\site-packages\sqlalchemy\engine\base.py", line 1249, in _execute_context
    self._handle_dbapi_exception(
  File "E:\GraduationWork\ENV\lib\site-packages\sqlalchemy\engine\base.py", line 1476, in _handle_dbapi_exception
    util.raise_from_cause(sqlalchemy_exception, exc_info)
  File "E:\GraduationWork\ENV\lib\site-packages\sqlalchemy\util\compat.py", line 398, in raise_from_cause
    reraise(type(exception), exception, tb=exc_tb, cause=cause)
  File "E:\GraduationWork\ENV\lib\site-packages\sqlalchemy\util\compat.py", line 152, in reraise
    raise value.with_traceback(tb)
  File "E:\GraduationWork\ENV\lib\site-packages\sqlalchemy\engine\base.py", line 1245, in _execute_context
    self.dialect.do_execute(
  File "E:\GraduationWork\ENV\lib\site-packages\sqlalchemy\engine\default.py", line 581, in do_execute
    cursor.execute(statement, parameters)
  File "E:\GraduationWork\ENV\lib\site-packages\mysql\connector\cursor.py", line 551, in execute
    self._handle_result(self._connection.cmd_query(stmt))
  File "E:\GraduationWork\ENV\lib\site-packages\mysql\connector\connection.py", line 490, in cmd_query
    result = self._handle_result(self._send_cmd(ServerCmd.QUERY, query))
  File "E:\GraduationWork\ENV\lib\site-packages\mysql\connector\connection.py", line 395, in _handle_result
    raise errors.get_exception(packet)
sqlalchemy.exc.ProgrammingError: (mysql.connector.errors.ProgrammingError) 1146 (42S02): Table 'sql7323829.employee' doesn't exist
[SQL: SELECT employee.id AS employee_id, employee.name AS employee_name, employee.department_id AS employee_department_id, employee.date_of_birthday AS employee_date_of_birthday, employee.salary AS employee_salary 
FROM employee]
(Background on this error at: http://sqlalche.me/e/f405)
2020-02-22 23:19:17,200 - service.crud - DEBUG - List of employees was returned
2020-02-22 23:19:17,822 - rest.api - ERROR - Exception on /api/employees [GET]
Traceback (most recent call last):
  File "E:\GraduationWork\ENV\lib\site-packages\sqlalchemy\engine\base.py", line 1245, in _execute_context
    self.dialect.do_execute(
  File "E:\GraduationWork\ENV\lib\site-packages\sqlalchemy\engine\default.py", line 581, in do_execute
    cursor.execute(statement, parameters)
  File "E:\GraduationWork\ENV\lib\site-packages\mysql\connector\cursor.py", line 551, in execute
    self._handle_result(self._connection.cmd_query(stmt))
  File "E:\GraduationWork\ENV\lib\site-packages\mysql\connector\connection.py", line 490, in cmd_query
    result = self._handle_result(self._send_cmd(ServerCmd.QUERY, query))
  File "E:\GraduationWork\ENV\lib\site-packages\mysql\connector\connection.py", line 395, in _handle_result
    raise errors.get_exception(packet)
mysql.connector.errors.ProgrammingError: 1146 (42S02): Table 'sql7323829.employee' doesn't exist

The above exception was the direct cause of the following exception:

Traceback (most recent call last):
  File "E:\GraduationWork\ENV\lib\site-packages\flask\app.py", line 1949, in full_dispatch_request
    rv = self.dispatch_request()
  File "E:\GraduationWork\ENV\lib\site-packages\flask\app.py", line 1935, in dispatch_request
    return self.view_functions[rule.endpoint](**req.view_args)
  File "E:\GraduationWork\ENV\lib\site-packages\flask_restful\__init__.py", line 458, in wrapper
    resp = resource(*args, **kwargs)
  File "E:\GraduationWork\ENV\lib\site-packages\flask\views.py", line 89, in view
    return self.dispatch_request(*args, **kwargs)
  File "E:\GraduationWork\ENV\lib\site-packages\flask_restful\__init__.py", line 573, in dispatch_request
    resp = meth(*args, **kwargs)
  File "E:\GraduationWork\DepartmentHandler\department-app\rest\api.py", line 180, in get
    employees = crud.Employees.get_all()
  File "E:\GraduationWork\DepartmentHandler\department-app\service\crud.py", line 128, in get_all
    return Employee.query.all()
  File "E:\GraduationWork\ENV\lib\site-packages\sqlalchemy\orm\query.py", line 3211, in all
    return list(self)
  File "E:\GraduationWork\ENV\lib\site-packages\sqlalchemy\orm\query.py", line 3367, in __iter__
    return self._execute_and_instances(context)
  File "E:\GraduationWork\ENV\lib\site-packages\sqlalchemy\orm\query.py", line 3392, in _execute_and_instances
    result = conn.execute(querycontext.statement, self._params)
  File "E:\GraduationWork\ENV\lib\site-packages\sqlalchemy\engine\base.py", line 982, in execute
    return meth(self, multiparams, params)
  File "E:\GraduationWork\ENV\lib\site-packages\sqlalchemy\sql\elements.py", line 287, in _execute_on_connection
    return connection._execute_clauseelement(self, multiparams, params)
  File "E:\GraduationWork\ENV\lib\site-packages\sqlalchemy\engine\base.py", line 1095, in _execute_clauseelement
    ret = self._execute_context(
  File "E:\GraduationWork\ENV\lib\site-packages\sqlalchemy\engine\base.py", line 1249, in _execute_context
    self._handle_dbapi_exception(
  File "E:\GraduationWork\ENV\lib\site-packages\sqlalchemy\engine\base.py", line 1476, in _handle_dbapi_exception
    util.raise_from_cause(sqlalchemy_exception, exc_info)
  File "E:\GraduationWork\ENV\lib\site-packages\sqlalchemy\util\compat.py", line 398, in raise_from_cause
    reraise(type(exception), exception, tb=exc_tb, cause=cause)
  File "E:\GraduationWork\ENV\lib\site-packages\sqlalchemy\util\compat.py", line 152, in reraise
    raise value.with_traceback(tb)
  File "E:\GraduationWork\ENV\lib\site-packages\sqlalchemy\engine\base.py", line 1245, in _execute_context
    self.dialect.do_execute(
  File "E:\GraduationWork\ENV\lib\site-packages\sqlalchemy\engine\default.py", line 581, in do_execute
    cursor.execute(statement, parameters)
  File "E:\GraduationWork\ENV\lib\site-packages\mysql\connector\cursor.py", line 551, in execute
    self._handle_result(self._connection.cmd_query(stmt))
  File "E:\GraduationWork\ENV\lib\site-packages\mysql\connector\connection.py", line 490, in cmd_query
    result = self._handle_result(self._send_cmd(ServerCmd.QUERY, query))
  File "E:\GraduationWork\ENV\lib\site-packages\mysql\connector\connection.py", line 395, in _handle_result
    raise errors.get_exception(packet)
sqlalchemy.exc.ProgrammingError: (mysql.connector.errors.ProgrammingError) 1146 (42S02): Table 'sql7323829.employee' doesn't exist
[SQL: SELECT employee.id AS employee_id, employee.name AS employee_name, employee.department_id AS employee_department_id, employee.date_of_birthday AS employee_date_of_birthday, employee.salary AS employee_salary 
FROM employee]
(Background on this error at: http://sqlalche.me/e/f405)
2020-02-22 23:19:20,244 - rest.api - ERROR - Exception on /api/departments-ids [GET]
Traceback (most recent call last):
  File "E:\GraduationWork\ENV\lib\site-packages\sqlalchemy\engine\base.py", line 1245, in _execute_context
    self.dialect.do_execute(
  File "E:\GraduationWork\ENV\lib\site-packages\sqlalchemy\engine\default.py", line 581, in do_execute
    cursor.execute(statement, parameters)
  File "E:\GraduationWork\ENV\lib\site-packages\mysql\connector\cursor.py", line 551, in execute
    self._handle_result(self._connection.cmd_query(stmt))
  File "E:\GraduationWork\ENV\lib\site-packages\mysql\connector\connection.py", line 490, in cmd_query
    result = self._handle_result(self._send_cmd(ServerCmd.QUERY, query))
  File "E:\GraduationWork\ENV\lib\site-packages\mysql\connector\connection.py", line 395, in _handle_result
    raise errors.get_exception(packet)
mysql.connector.errors.ProgrammingError: 1146 (42S02): Table 'sql7323829.department' doesn't exist

The above exception was the direct cause of the following exception:

Traceback (most recent call last):
  File "E:\GraduationWork\ENV\lib\site-packages\flask\app.py", line 1949, in full_dispatch_request
    rv = self.dispatch_request()
  File "E:\GraduationWork\ENV\lib\site-packages\flask\app.py", line 1935, in dispatch_request
    return self.view_functions[rule.endpoint](**req.view_args)
  File "E:\GraduationWork\ENV\lib\site-packages\flask_restful\__init__.py", line 458, in wrapper
    resp = resource(*args, **kwargs)
  File "E:\GraduationWork\ENV\lib\site-packages\flask\views.py", line 89, in view
    return self.dispatch_request(*args, **kwargs)
  File "E:\GraduationWork\ENV\lib\site-packages\flask_restful\__init__.py", line 573, in dispatch_request
    resp = meth(*args, **kwargs)
  File "E:\GraduationWork\DepartmentHandler\department-app\rest\api.py", line 83, in get
    departments = crud.Departments.get_all()[0]
  File "E:\GraduationWork\DepartmentHandler\department-app\service\crud.py", line 32, in get_all
    departments = Department.query.all()
  File "E:\GraduationWork\ENV\lib\site-packages\sqlalchemy\orm\query.py", line 3211, in all
    return list(self)
  File "E:\GraduationWork\ENV\lib\site-packages\sqlalchemy\orm\query.py", line 3367, in __iter__
    return self._execute_and_instances(context)
  File "E:\GraduationWork\ENV\lib\site-packages\sqlalchemy\orm\query.py", line 3392, in _execute_and_instances
    result = conn.execute(querycontext.statement, self._params)
  File "E:\GraduationWork\ENV\lib\site-packages\sqlalchemy\engine\base.py", line 982, in execute
    return meth(self, multiparams, params)
  File "E:\GraduationWork\ENV\lib\site-packages\sqlalchemy\sql\elements.py", line 287, in _execute_on_connection
    return connection._execute_clauseelement(self, multiparams, params)
  File "E:\GraduationWork\ENV\lib\site-packages\sqlalchemy\engine\base.py", line 1095, in _execute_clauseelement
    ret = self._execute_context(
  File "E:\GraduationWork\ENV\lib\site-packages\sqlalchemy\engine\base.py", line 1249, in _execute_context
    self._handle_dbapi_exception(
  File "E:\GraduationWork\ENV\lib\site-packages\sqlalchemy\engine\base.py", line 1476, in _handle_dbapi_exception
    util.raise_from_cause(sqlalchemy_exception, exc_info)
  File "E:\GraduationWork\ENV\lib\site-packages\sqlalchemy\util\compat.py", line 398, in raise_from_cause
    reraise(type(exception), exception, tb=exc_tb, cause=cause)
  File "E:\GraduationWork\ENV\lib\site-packages\sqlalchemy\util\compat.py", line 152, in reraise
    raise value.with_traceback(tb)
  File "E:\GraduationWork\ENV\lib\site-packages\sqlalchemy\engine\base.py", line 1245, in _execute_context
    self.dialect.do_execute(
  File "E:\GraduationWork\ENV\lib\site-packages\sqlalchemy\engine\default.py", line 581, in do_execute
    cursor.execute(statement, parameters)
  File "E:\GraduationWork\ENV\lib\site-packages\mysql\connector\cursor.py", line 551, in execute
    self._handle_result(self._connection.cmd_query(stmt))
  File "E:\GraduationWork\ENV\lib\site-packages\mysql\connector\connection.py", line 490, in cmd_query
    result = self._handle_result(self._send_cmd(ServerCmd.QUERY, query))
  File "E:\GraduationWork\ENV\lib\site-packages\mysql\connector\connection.py", line 395, in _handle_result
    raise errors.get_exception(packet)
sqlalchemy.exc.ProgrammingError: (mysql.connector.errors.ProgrammingError) 1146 (42S02): Table 'sql7323829.department' doesn't exist
[SQL: SELECT department.id AS department_id, department.name AS department_name 
FROM department]
(Background on this error at: http://sqlalche.me/e/f405)
2020-02-22 23:19:39,484 - rest.api - ERROR - Exception on /api/departments-ids [GET]
Traceback (most recent call last):
  File "E:\GraduationWork\ENV\lib\site-packages\sqlalchemy\engine\base.py", line 1245, in _execute_context
    self.dialect.do_execute(
  File "E:\GraduationWork\ENV\lib\site-packages\sqlalchemy\engine\default.py", line 581, in do_execute
    cursor.execute(statement, parameters)
  File "E:\GraduationWork\ENV\lib\site-packages\mysql\connector\cursor.py", line 551, in execute
    self._handle_result(self._connection.cmd_query(stmt))
  File "E:\GraduationWork\ENV\lib\site-packages\mysql\connector\connection.py", line 490, in cmd_query
    result = self._handle_result(self._send_cmd(ServerCmd.QUERY, query))
  File "E:\GraduationWork\ENV\lib\site-packages\mysql\connector\connection.py", line 395, in _handle_result
    raise errors.get_exception(packet)
mysql.connector.errors.ProgrammingError: 1146 (42S02): Table 'sql7323829.department' doesn't exist

The above exception was the direct cause of the following exception:

Traceback (most recent call last):
  File "E:\GraduationWork\ENV\lib\site-packages\flask\app.py", line 1949, in full_dispatch_request
    rv = self.dispatch_request()
  File "E:\GraduationWork\ENV\lib\site-packages\flask\app.py", line 1935, in dispatch_request
    return self.view_functions[rule.endpoint](**req.view_args)
  File "E:\GraduationWork\ENV\lib\site-packages\flask_restful\__init__.py", line 458, in wrapper
    resp = resource(*args, **kwargs)
  File "E:\GraduationWork\ENV\lib\site-packages\flask\views.py", line 89, in view
    return self.dispatch_request(*args, **kwargs)
  File "E:\GraduationWork\ENV\lib\site-packages\flask_restful\__init__.py", line 573, in dispatch_request
    resp = meth(*args, **kwargs)
  File "E:\GraduationWork\DepartmentHandler\department-app\rest\api.py", line 83, in get
    departments = crud.Departments.get_all()[0]
  File "E:\GraduationWork\DepartmentHandler\department-app\service\crud.py", line 32, in get_all
    departments = Department.query.all()
  File "E:\GraduationWork\ENV\lib\site-packages\sqlalchemy\orm\query.py", line 3211, in all
    return list(self)
  File "E:\GraduationWork\ENV\lib\site-packages\sqlalchemy\orm\query.py", line 3367, in __iter__
    return self._execute_and_instances(context)
  File "E:\GraduationWork\ENV\lib\site-packages\sqlalchemy\orm\query.py", line 3392, in _execute_and_instances
    result = conn.execute(querycontext.statement, self._params)
  File "E:\GraduationWork\ENV\lib\site-packages\sqlalchemy\engine\base.py", line 982, in execute
    return meth(self, multiparams, params)
  File "E:\GraduationWork\ENV\lib\site-packages\sqlalchemy\sql\elements.py", line 287, in _execute_on_connection
    return connection._execute_clauseelement(self, multiparams, params)
  File "E:\GraduationWork\ENV\lib\site-packages\sqlalchemy\engine\base.py", line 1095, in _execute_clauseelement
    ret = self._execute_context(
  File "E:\GraduationWork\ENV\lib\site-packages\sqlalchemy\engine\base.py", line 1249, in _execute_context
    self._handle_dbapi_exception(
  File "E:\GraduationWork\ENV\lib\site-packages\sqlalchemy\engine\base.py", line 1476, in _handle_dbapi_exception
    util.raise_from_cause(sqlalchemy_exception, exc_info)
  File "E:\GraduationWork\ENV\lib\site-packages\sqlalchemy\util\compat.py", line 398, in raise_from_cause
    reraise(type(exception), exception, tb=exc_tb, cause=cause)
  File "E:\GraduationWork\ENV\lib\site-packages\sqlalchemy\util\compat.py", line 152, in reraise
    raise value.with_traceback(tb)
  File "E:\GraduationWork\ENV\lib\site-packages\sqlalchemy\engine\base.py", line 1245, in _execute_context
    self.dialect.do_execute(
  File "E:\GraduationWork\ENV\lib\site-packages\sqlalchemy\engine\default.py", line 581, in do_execute
    cursor.execute(statement, parameters)
  File "E:\GraduationWork\ENV\lib\site-packages\mysql\connector\cursor.py", line 551, in execute
    self._handle_result(self._connection.cmd_query(stmt))
  File "E:\GraduationWork\ENV\lib\site-packages\mysql\connector\connection.py", line 490, in cmd_query
    result = self._handle_result(self._send_cmd(ServerCmd.QUERY, query))
  File "E:\GraduationWork\ENV\lib\site-packages\mysql\connector\connection.py", line 395, in _handle_result
    raise errors.get_exception(packet)
sqlalchemy.exc.ProgrammingError: (mysql.connector.errors.ProgrammingError) 1146 (42S02): Table 'sql7323829.department' doesn't exist
[SQL: SELECT department.id AS department_id, department.name AS department_name 
FROM department]
(Background on this error at: http://sqlalche.me/e/f405)
2020-02-22 23:21:56,952 - rest.api - ERROR - Exception on /api/departments-ids [GET]
Traceback (most recent call last):
  File "E:\GraduationWork\ENV\lib\site-packages\sqlalchemy\engine\base.py", line 1245, in _execute_context
    self.dialect.do_execute(
  File "E:\GraduationWork\ENV\lib\site-packages\sqlalchemy\engine\default.py", line 581, in do_execute
    cursor.execute(statement, parameters)
  File "E:\GraduationWork\ENV\lib\site-packages\mysql\connector\cursor.py", line 551, in execute
    self._handle_result(self._connection.cmd_query(stmt))
  File "E:\GraduationWork\ENV\lib\site-packages\mysql\connector\connection.py", line 490, in cmd_query
    result = self._handle_result(self._send_cmd(ServerCmd.QUERY, query))
  File "E:\GraduationWork\ENV\lib\site-packages\mysql\connector\connection.py", line 395, in _handle_result
    raise errors.get_exception(packet)
mysql.connector.errors.ProgrammingError: 1146 (42S02): Table 'sql7323829.department' doesn't exist

The above exception was the direct cause of the following exception:

Traceback (most recent call last):
  File "E:\GraduationWork\ENV\lib\site-packages\flask\app.py", line 1949, in full_dispatch_request
    rv = self.dispatch_request()
  File "E:\GraduationWork\ENV\lib\site-packages\flask\app.py", line 1935, in dispatch_request
    return self.view_functions[rule.endpoint](**req.view_args)
  File "E:\GraduationWork\ENV\lib\site-packages\flask_restful\__init__.py", line 458, in wrapper
    resp = resource(*args, **kwargs)
  File "E:\GraduationWork\ENV\lib\site-packages\flask\views.py", line 89, in view
    return self.dispatch_request(*args, **kwargs)
  File "E:\GraduationWork\ENV\lib\site-packages\flask_restful\__init__.py", line 573, in dispatch_request
    resp = meth(*args, **kwargs)
  File "E:\GraduationWork\DepartmentHandler\department-app\rest\api.py", line 83, in get
    departments = crud.Departments.get_all()[0]
  File "E:\GraduationWork\DepartmentHandler\department-app\service\crud.py", line 32, in get_all
    departments = Department.query.all()
  File "E:\GraduationWork\ENV\lib\site-packages\sqlalchemy\orm\query.py", line 3211, in all
    return list(self)
  File "E:\GraduationWork\ENV\lib\site-packages\sqlalchemy\orm\query.py", line 3367, in __iter__
    return self._execute_and_instances(context)
  File "E:\GraduationWork\ENV\lib\site-packages\sqlalchemy\orm\query.py", line 3392, in _execute_and_instances
    result = conn.execute(querycontext.statement, self._params)
  File "E:\GraduationWork\ENV\lib\site-packages\sqlalchemy\engine\base.py", line 982, in execute
    return meth(self, multiparams, params)
  File "E:\GraduationWork\ENV\lib\site-packages\sqlalchemy\sql\elements.py", line 287, in _execute_on_connection
    return connection._execute_clauseelement(self, multiparams, params)
  File "E:\GraduationWork\ENV\lib\site-packages\sqlalchemy\engine\base.py", line 1095, in _execute_clauseelement
    ret = self._execute_context(
  File "E:\GraduationWork\ENV\lib\site-packages\sqlalchemy\engine\base.py", line 1249, in _execute_context
    self._handle_dbapi_exception(
  File "E:\GraduationWork\ENV\lib\site-packages\sqlalchemy\engine\base.py", line 1476, in _handle_dbapi_exception
    util.raise_from_cause(sqlalchemy_exception, exc_info)
  File "E:\GraduationWork\ENV\lib\site-packages\sqlalchemy\util\compat.py", line 398, in raise_from_cause
    reraise(type(exception), exception, tb=exc_tb, cause=cause)
  File "E:\GraduationWork\ENV\lib\site-packages\sqlalchemy\util\compat.py", line 152, in reraise
    raise value.with_traceback(tb)
  File "E:\GraduationWork\ENV\lib\site-packages\sqlalchemy\engine\base.py", line 1245, in _execute_context
    self.dialect.do_execute(
  File "E:\GraduationWork\ENV\lib\site-packages\sqlalchemy\engine\default.py", line 581, in do_execute
    cursor.execute(statement, parameters)
  File "E:\GraduationWork\ENV\lib\site-packages\mysql\connector\cursor.py", line 551, in execute
    self._handle_result(self._connection.cmd_query(stmt))
  File "E:\GraduationWork\ENV\lib\site-packages\mysql\connector\connection.py", line 490, in cmd_query
    result = self._handle_result(self._send_cmd(ServerCmd.QUERY, query))
  File "E:\GraduationWork\ENV\lib\site-packages\mysql\connector\connection.py", line 395, in _handle_result
    raise errors.get_exception(packet)
sqlalchemy.exc.ProgrammingError: (mysql.connector.errors.ProgrammingError) 1146 (42S02): Table 'sql7323829.department' doesn't exist
[SQL: SELECT department.id AS department_id, department.name AS department_name 
FROM department]
(Background on this error at: http://sqlalche.me/e/f405)
2020-02-22 23:23:01,363 - rest.api - ERROR - Exception on /api/departments-ids [GET]
Traceback (most recent call last):
  File "E:\GraduationWork\ENV\lib\site-packages\sqlalchemy\engine\base.py", line 1245, in _execute_context
    self.dialect.do_execute(
  File "E:\GraduationWork\ENV\lib\site-packages\sqlalchemy\engine\default.py", line 581, in do_execute
    cursor.execute(statement, parameters)
  File "E:\GraduationWork\ENV\lib\site-packages\mysql\connector\cursor.py", line 551, in execute
    self._handle_result(self._connection.cmd_query(stmt))
  File "E:\GraduationWork\ENV\lib\site-packages\mysql\connector\connection.py", line 490, in cmd_query
    result = self._handle_result(self._send_cmd(ServerCmd.QUERY, query))
  File "E:\GraduationWork\ENV\lib\site-packages\mysql\connector\connection.py", line 395, in _handle_result
    raise errors.get_exception(packet)
mysql.connector.errors.ProgrammingError: 1146 (42S02): Table 'sql7323829.department' doesn't exist

The above exception was the direct cause of the following exception:

Traceback (most recent call last):
  File "E:\GraduationWork\ENV\lib\site-packages\flask\app.py", line 1949, in full_dispatch_request
    rv = self.dispatch_request()
  File "E:\GraduationWork\ENV\lib\site-packages\flask\app.py", line 1935, in dispatch_request
    return self.view_functions[rule.endpoint](**req.view_args)
  File "E:\GraduationWork\ENV\lib\site-packages\flask_restful\__init__.py", line 458, in wrapper
    resp = resource(*args, **kwargs)
  File "E:\GraduationWork\ENV\lib\site-packages\flask\views.py", line 89, in view
    return self.dispatch_request(*args, **kwargs)
  File "E:\GraduationWork\ENV\lib\site-packages\flask_restful\__init__.py", line 573, in dispatch_request
    resp = meth(*args, **kwargs)
  File "E:\GraduationWork\DepartmentHandler\department-app\rest\api.py", line 83, in get
    departments = crud.Departments.get_all()[0]
  File "E:\GraduationWork\DepartmentHandler\department-app\service\crud.py", line 32, in get_all
    departments = Department.query.all()
  File "E:\GraduationWork\ENV\lib\site-packages\sqlalchemy\orm\query.py", line 3211, in all
    return list(self)
  File "E:\GraduationWork\ENV\lib\site-packages\sqlalchemy\orm\query.py", line 3367, in __iter__
    return self._execute_and_instances(context)
  File "E:\GraduationWork\ENV\lib\site-packages\sqlalchemy\orm\query.py", line 3392, in _execute_and_instances
    result = conn.execute(querycontext.statement, self._params)
  File "E:\GraduationWork\ENV\lib\site-packages\sqlalchemy\engine\base.py", line 982, in execute
    return meth(self, multiparams, params)
  File "E:\GraduationWork\ENV\lib\site-packages\sqlalchemy\sql\elements.py", line 287, in _execute_on_connection
    return connection._execute_clauseelement(self, multiparams, params)
  File "E:\GraduationWork\ENV\lib\site-packages\sqlalchemy\engine\base.py", line 1095, in _execute_clauseelement
    ret = self._execute_context(
  File "E:\GraduationWork\ENV\lib\site-packages\sqlalchemy\engine\base.py", line 1249, in _execute_context
    self._handle_dbapi_exception(
  File "E:\GraduationWork\ENV\lib\site-packages\sqlalchemy\engine\base.py", line 1476, in _handle_dbapi_exception
    util.raise_from_cause(sqlalchemy_exception, exc_info)
  File "E:\GraduationWork\ENV\lib\site-packages\sqlalchemy\util\compat.py", line 398, in raise_from_cause
    reraise(type(exception), exception, tb=exc_tb, cause=cause)
  File "E:\GraduationWork\ENV\lib\site-packages\sqlalchemy\util\compat.py", line 152, in reraise
    raise value.with_traceback(tb)
  File "E:\GraduationWork\ENV\lib\site-packages\sqlalchemy\engine\base.py", line 1245, in _execute_context
    self.dialect.do_execute(
  File "E:\GraduationWork\ENV\lib\site-packages\sqlalchemy\engine\default.py", line 581, in do_execute
    cursor.execute(statement, parameters)
  File "E:\GraduationWork\ENV\lib\site-packages\mysql\connector\cursor.py", line 551, in execute
    self._handle_result(self._connection.cmd_query(stmt))
  File "E:\GraduationWork\ENV\lib\site-packages\mysql\connector\connection.py", line 490, in cmd_query
    result = self._handle_result(self._send_cmd(ServerCmd.QUERY, query))
  File "E:\GraduationWork\ENV\lib\site-packages\mysql\connector\connection.py", line 395, in _handle_result
    raise errors.get_exception(packet)
sqlalchemy.exc.ProgrammingError: (mysql.connector.errors.ProgrammingError) 1146 (42S02): Table 'sql7323829.department' doesn't exist
[SQL: SELECT department.id AS department_id, department.name AS department_name 
FROM department]
(Background on this error at: http://sqlalche.me/e/f405)
2020-02-22 23:32:46,109 - rest.api - ERROR - Exception on /api/departments [GET]
Traceback (most recent call last):
  File "E:\GraduationWork\ENV\lib\site-packages\sqlalchemy\engine\base.py", line 1245, in _execute_context
    self.dialect.do_execute(
  File "E:\GraduationWork\ENV\lib\site-packages\sqlalchemy\engine\default.py", line 581, in do_execute
    cursor.execute(statement, parameters)
  File "E:\GraduationWork\ENV\lib\site-packages\mysql\connector\cursor.py", line 551, in execute
    self._handle_result(self._connection.cmd_query(stmt))
  File "E:\GraduationWork\ENV\lib\site-packages\mysql\connector\connection.py", line 490, in cmd_query
    result = self._handle_result(self._send_cmd(ServerCmd.QUERY, query))
  File "E:\GraduationWork\ENV\lib\site-packages\mysql\connector\connection.py", line 395, in _handle_result
    raise errors.get_exception(packet)
mysql.connector.errors.ProgrammingError: 1146 (42S02): Table 'sql7323829.department' doesn't exist

The above exception was the direct cause of the following exception:

Traceback (most recent call last):
  File "E:\GraduationWork\ENV\lib\site-packages\flask\app.py", line 1949, in full_dispatch_request
    rv = self.dispatch_request()
  File "E:\GraduationWork\ENV\lib\site-packages\flask\app.py", line 1935, in dispatch_request
    return self.view_functions[rule.endpoint](**req.view_args)
  File "E:\GraduationWork\ENV\lib\site-packages\flask_restful\__init__.py", line 458, in wrapper
    resp = resource(*args, **kwargs)
  File "E:\GraduationWork\ENV\lib\site-packages\flask\views.py", line 89, in view
    return self.dispatch_request(*args, **kwargs)
  File "E:\GraduationWork\ENV\lib\site-packages\flask_restful\__init__.py", line 573, in dispatch_request
    resp = meth(*args, **kwargs)
  File "E:\GraduationWork\DepartmentHandler\department-app\rest\api.py", line 50, in get
    data = crud.Departments.get_all()
  File "E:\GraduationWork\DepartmentHandler\department-app\service\crud.py", line 32, in get_all
    departments = Department.query.all()
  File "E:\GraduationWork\ENV\lib\site-packages\sqlalchemy\orm\query.py", line 3211, in all
    return list(self)
  File "E:\GraduationWork\ENV\lib\site-packages\sqlalchemy\orm\query.py", line 3367, in __iter__
    return self._execute_and_instances(context)
  File "E:\GraduationWork\ENV\lib\site-packages\sqlalchemy\orm\query.py", line 3392, in _execute_and_instances
    result = conn.execute(querycontext.statement, self._params)
  File "E:\GraduationWork\ENV\lib\site-packages\sqlalchemy\engine\base.py", line 982, in execute
    return meth(self, multiparams, params)
  File "E:\GraduationWork\ENV\lib\site-packages\sqlalchemy\sql\elements.py", line 287, in _execute_on_connection
    return connection._execute_clauseelement(self, multiparams, params)
  File "E:\GraduationWork\ENV\lib\site-packages\sqlalchemy\engine\base.py", line 1095, in _execute_clauseelement
    ret = self._execute_context(
  File "E:\GraduationWork\ENV\lib\site-packages\sqlalchemy\engine\base.py", line 1249, in _execute_context
    self._handle_dbapi_exception(
  File "E:\GraduationWork\ENV\lib\site-packages\sqlalchemy\engine\base.py", line 1476, in _handle_dbapi_exception
    util.raise_from_cause(sqlalchemy_exception, exc_info)
  File "E:\GraduationWork\ENV\lib\site-packages\sqlalchemy\util\compat.py", line 398, in raise_from_cause
    reraise(type(exception), exception, tb=exc_tb, cause=cause)
  File "E:\GraduationWork\ENV\lib\site-packages\sqlalchemy\util\compat.py", line 152, in reraise
    raise value.with_traceback(tb)
  File "E:\GraduationWork\ENV\lib\site-packages\sqlalchemy\engine\base.py", line 1245, in _execute_context
    self.dialect.do_execute(
  File "E:\GraduationWork\ENV\lib\site-packages\sqlalchemy\engine\default.py", line 581, in do_execute
    cursor.execute(statement, parameters)
  File "E:\GraduationWork\ENV\lib\site-packages\mysql\connector\cursor.py", line 551, in execute
    self._handle_result(self._connection.cmd_query(stmt))
  File "E:\GraduationWork\ENV\lib\site-packages\mysql\connector\connection.py", line 490, in cmd_query
    result = self._handle_result(self._send_cmd(ServerCmd.QUERY, query))
  File "E:\GraduationWork\ENV\lib\site-packages\mysql\connector\connection.py", line 395, in _handle_result
    raise errors.get_exception(packet)
sqlalchemy.exc.ProgrammingError: (mysql.connector.errors.ProgrammingError) 1146 (42S02): Table 'sql7323829.department' doesn't exist
[SQL: SELECT department.id AS department_id, department.name AS department_name 
FROM department]
(Background on this error at: http://sqlalche.me/e/f405)
